Workbook
Name TaxTV: 10%
Name \p: '[1]FA-LISTING'!#REF!
Name BuiltIn_AutoFilter___3: "$"
Name 文件管制作業辦法: "圖片 1"

Sheet DB小板汇总
A1: 6.71 | E1: 币种:USD
A2: 机型 | B2: 日期 | C2: 原汇率 | D2: 料号 | E2: SKU | F2: PCB | G2: PCB | H2: PCB | I2: Others | J2: Others | K2: SMT | L2: TTL | N2: 备注
A3: XN21S | B3: 46081 | C3: 6.837 | D3: A.F.D.2400329-PVT | E3: A.F.D.2400329 RJ45 DB | F3: =6.038/C3/1.13 -> 0.78153618 | G3: 0.93784341 | H3: 1.0316278 | I3: 3.41 | J3: =I3*1.05 -> 3.5805 | K3: 0.4 | L3: =SUBTOTAL(109,H3,J3,K3) -> 5.0121278 | M3: 3.1 | N3: 含RTL8111H；含GL850G；PS8719ETQFN24GTR2-A0
A4: DA1021C | B4: 46081 | C4: 6.837 | D4: A.F.D.2500004-PVT | E4: A.F.D.2500004 RJ45 DB | F4: 0.41662386 | G4: 0.49994863 | H4: 0.54994349 | I4: 2.6155851 | J4: =I4*1.05 -> 2.7463644 | K4: 0.4 | L4: =SUBTOTAL(109,H4,J4,K4) -> 3.6963079 | M4: 2.3778047 | N4: 含RTL8111H；含GL850G；RTS5170
A5: XN21 | B5: 46285 | C5: 6.7 | D5: A.F.D.2300285 | E5: A.F.D.2300285 RJ45 DB | F5: =4/C5/1.13*1.1 -> 0.58116497 | G5: 0.68865107 | H5: =4.33/C5/1.13 -> 0.57191917 | I5: 2.8349495 | J5: 2.8 | K5: 0.4 | L5: =SUBTOTAL(109,H5,J5,K5) -> 3.7719192 | M5: 2.5772269 | N5: 含有8111H
B6: 20240105 | C6: 6.837 | D6: A.P.10001018 | E6: A.P.10001018 RJ45 DB | F6: 0.72182853 | G6: 0.86619424 | H6: 0.95281366 | I6: 3.3077268 | J6: =I6*1.05 -> 3.4731131 | K6: 0.4 | L6: =SUBTOTAL(109,H6,J6,K6) -> 4.8259268 | M6: 3.0070243 | N6: 8111H
B7: 20241105 | C7: 6.837 | D7: A.F.D.2400048-MP | E7: A.F.D.2400048 USB DB | F7: 0.17745375 | G7: 0.21294449 | H7: 0.23423894 | I7: 1.7055684 | J7: =I7*1.05 -> 1.7908468 | K7: 0.2 | L7: =SUBTOTAL(109,H7,J7,K7) -> 2.2250857 | M7: 1.5505167 | N7: 含有IT66318FN
B8: 20240411 | C8: 6.837 | D8: A.F.D.2400049-MP | E8: A.F.D.2400049 USB DB | F8: 0.16021508 | G8: 0.1922581 | H8: 0.21148391 | I8: 0.65508274 | J8: =I8*1.05 -> 0.68783688 | K8: 0.2 | L8: =SUBTOTAL(109,H8,J8,K8) -> 1.0993208 | M8: 0.59552977
B9: 20240411 | C9: 6.837 | D9: A.F.D.2400058-MP | E9: A.F.D.2400058 TYPEC_DB | F9: 0.33350371 | G9: 0.40020445 | H9: 0.4402249 | I9: 2.691534 | J9: =I9*1.05 -> 2.8261107 | K9: 0.3 | L9: =SUBTOTAL(109,H9,J9,K9) -> 3.5663356 | M9: 2.4468491 | N9: 含有ALC269Q
B10: 20240411 | C10: 6.837 | D10: A.F.D.2400080-MP | E10: A.F.D.2400080 TYPEC_DB | F10: 0.33350371 | G10: 0.40020445 | H10: 0.4402249 | I10: 3.227697 | J10: =I10*1.05 -> 3.3890818 | K10: 0.3 | L10: =SUBTOTAL(109,H10,J10,K10) -> 4.1293067 | M10: 2.93427 | N10: 含有ALC269Q
B11: 20241105 | C11: 6.837 | D11: A.F.D.2300338-MP | E11: A.F.D.2300338 140M_SS_TYPEC_DB | F11: 0.34485622 | G11: 0.41382747 | H11: 0.45521021 | I11: 3.4072901 | J11: =I11*1.05 -> 3.5776546 | K11: 0.4 | L11: =SUBTOTAL(109,H11,J11,K11) -> 4.4328649 | M11: 3.0975365
C12: 6.837 | E12: A.F.D.2300246 140M_SS_TYPEC_DB | F12: 0.4242062 | G12: 0.50904743 | H12: 0.55995218 | I12: 3.5449491 | J12: =I12*1.05 -> 3.7221965 | K12: 0.4 | L12: =SUBTOTAL(109,H12,J12,K12) -> 4.6821487 | M12: 3.222681
A13: AXN88 | C13: 6.837 | E13: A.F.D.2300339 140M-SS_DB | F13: 0.15785612 | G13: 0.18942735 | H13: 0.20837008 | I13: 1.6917892 | J13: =I13*1.05 -> 1.7763787 | K13: 0.2 | L13: =SUBTOTAL(109,H13,J13,K13) -> 2.1847488 | M13: 1.5379902
A14: XN25 | B14: 46122 | C14: 6.837 | D14: A.F.D.2400234-PVT | E14: A.F.D.2400234 TYPEC DB | F14: =0.454147943452342*1.2 -> 0.54497753 | G14: 0.65397304 | H14: 0.71937034 | I14: 1.5036129 | J14: =I14*1.05 -> 1.5787936 | K14: =2.3/C14 -> 0.33640486 | L14: =SUBTOTAL(109,H14,J14,K14) -> 2.6345688 | M14: 1.3669209 | N14: 含有SN6140,
B15: 20250114 | C15: 6.78 | D15: A.F.D.2400198-MP | E15: A.F.D.2400198 RJ45 DB | F15: =5.5/C15/1.13*1.2 -> 0.86146135 | G15: 1.0337536 | H15: 1.137129 | I15: 4.0013867 | J15: =I15*1.05 -> 4.201456 | K15: =2.8/C15 -> 0.41297935 | L15: =SUBTOTAL(109,H15,J15,K15) -> 5.7515643 | M15: 3.6376242 | N15: 含有RTL8111H；ALC269Q；OZ711LV2
C16: 6.837 | E16: A.F.D.2400171 RJ45 DB | F16: 0.53613905 | G16: 0.64336686 | H16: 0.70770355 | I16: 4.0899782 | J16: =I16*1.05 -> 4.2944771 | K16: 0.4 | L16: =SUBTOTAL(109,H16,J16,K16) -> 5.4021806 | M16: 3.718162 | N16: 含有8111H;ALC269Q
A17: DN50Z | B17: 20240625 | C17: 6.837 | D17: A.F.D.2300323-MP | E17: A.F.D.2300323 USB DB | F17: 0.38716667 | G17: 0.4646 | H17: 0.51106 | I17: 3.0333373 | J17: =I17*1.05 -> 3.1850041 | K17: 0.2 | L17: =SUBTOTAL(109,H17,J17,K17) -> 3.8960641 | M17: 2.7575793
B18: 20241030 | C18: 6.837 | D18: A.F.D.2300239-MP | E18: A.F.D.2300239 RJ45 DB | F18: 0.59640776 | G18: 0.71568931 | H18: 0.78725825 | I18: 7.7942757 | J18: =I18*1.05 -> 8.1839895 | K18: 0.4 | L18: =SUBTOTAL(109,H18,J18,K18) -> 9.3712477 | M18: 7.0857052 | N18: 含INTEL网卡ic-I226LM_SRKTT；ALC269Q；FG24102SEG（后期换料）
A19: XN50(6L+通孔+沉金） | B19: 20241030 | C19: 6.7739 | D19: A.F.D.2300240-MP | E19: A.F.D.2300240 RJ45 DB | F19: =6.26/C19/1.13 -> 0.81781884 | G19: 0.9813826 | H19: 1.0795209 | I19: 6.98775 | J19: =I19*1.05 -> 7.3371375 | K19: 0.4 | L19: =SUBTOTAL(109,H19,J19,K19) -> 8.8166584 | M19: =6.05*1.05 -> 6.3525 | N19: 含INTEL网卡ic-I226V_SRKTV；ALC269Q；FG24102SEG（后期换料）
A20: DN50Z | B20: 2025 0226 | C20: 6.837 | D20: A.F.D.2300324-MP | E20: A.F.D.2300324 USB DB | F20: 0.38877095 | G20: 0.46652513 | H20: 0.51317765 | I20: 3.3545245 | J20: =I20*1.05 -> 3.5222507 | K20: 0.2 | L20: =SUBTOTAL(109,H20,J20,K20) -> 4.2354283 | M20: 3.0495677 | N20: ALC269Q
C21: 6.837 | E21: A.P.10001155 140HC_YD_DB | F21: 0.43281173 | G21: 0.51937407 | H21: 0.57131148 | I21: 3.2229098 | J21: =I21*1.05 -> 3.3840553 | K21: 0.4 | L21: =SUBTOTAL(109,H21,J21,K21) -> 4.3553668 | M21: 2.929918
C22: 6.837 | E22: A.P.10001028 RJ45 DB | F22: 0.77676975 | G22: 0.9321237 | H22: 1.0253361 | I22: 4.6184285 | J22: =I22*1.05 -> 4.8493499 | K22: 0.8 | L22: =SUBTOTAL(109,H22,J22,K22) -> 6.674686 | M22: 4.1985714 | N22: I219V，ALC269
C23: 6.837 | E23: A.P.10001065 4G USB DB | F23: 0.56121296 | G23: 0.67345555 | H23: 0.7408011 | I23: 4.0989964 | J23: =I23*1.05 -> 4.3039463 | K23: 0.4 | L23: =SUBTOTAL(109,H23,J23,K23) -> 5.4447474 | M23: 3.7263604
C24: 6.837 | E24: A.P.10001028 RJ45 DB | F24: 0.77676975 | G24: 0.9321237 | H24: 1.0253361 | I24: 4.6184285 | J24: =I24*1.05 -> 4.8493499 | K24: 0.4 | L24: =SUBTOTAL(109,H24,J24,K24) -> 6.274686 | M24: 4.1985714 | N24: I219V，ALC269
B25: 20241115 | C25: 6.837 | D25: A.F.D.2300380-PVT | E25: A.F.D.2300380 USB DB | F25: 0.45234837 | G25: 0.54281804 | H25: 0.59709984 | I25: 2.5466575 | J25: =I25*1.05 -> 2.6739904 | K25: 0.2 | L25: =SUBTOTAL(109,H25,J25,K25) -> 3.4710903 | M25: 2.3151432 | N25: ALC269Q-VC3-GR;PS8719ETQFN24GTR2;RTS5170-GR
B26: 20250715 | C26: 6.837 | D26: A.P.10001066 | E26: A.P.10001066 AUDIO DB | F26: 7.0396087 | G26: 8.4475304 | H26: 9.2922835 | I26: 1.7971733 | J26: =I26*1.05 -> 1.887032 | K26: 0.2 | L26: =SUBTOTAL(109,H26,J26,K26) -> 11.379315 | M26: 1.6337939 | N26: 含在主板BOM里面的 需合计
B27: 20250218 | C27: 6.837 | D27: A.F.D.2300201-MP | E27: A.F.D.2300201 AUDIO DB | F27: 0.34837229 | G27: 0.41804675 | H27: 0.45985142 | I27: 1.8192269 | J27: =I27*1.05 -> 1.9101883 | K27: 0.2 | L27: =SUBTOTAL(109,H27,J27,K27) -> 2.5700397 | M27: 1.6538427 | N27: SN6140；RTS5170；PS8719ETQFN24GTR2-A0
B28: 20250807 | C28: 6.837 | D28: A.F.D.2500222-PVT | E28: A.F.D.2500222 RJ45 DB | F28: 0.4936802 | G28: 0.59241624 | H28: 0.65165787 | I28: 3.2774332 | J28: =I28*1.05 -> 3.4413048 | K28: 0.4 | L28: =SUBTOTAL(109,H28,J28,K28) -> 4.4929627 | M28: 2.9794847 | N28: 含8111H、ALC269Q
B29: 20240829 | C29: 6.837 | D29: A.F.D.2400221-EVT | E29: A.F.D.2400221 RJ45 DB | F29: 0.49957625 | G29: 0.5994915 | H29: 0.65944065 | I29: 3.0888772 | J29: =I29*1.05 -> 3.2433211 | K29: 0.4 | L29: =SUBTOTAL(109,H29,J29,K29) -> 4.3027617 | M29: 2.8080702 | N29: 含8111H
A30: DA1059E | B30: 20250516 | C30: 6.837 | E30: A.F.D.2300379 RJ45 DB | F30: 0.44991566 | G30: 0.53989879 | H30: 0.59388867 | I30: 3.683971 | J30: =I30*1.05 -> 3.8681696 | K30: 0.4 | L30: =SUBTOTAL(109,H30,J30,K30) -> 4.8620583 | M30: 3.3490646 | N30: 含8111H、ALC269Q
A31: MTNTU146L | B31: 46081 | C31: 6.837 | D31: A.F.D.2600043 | E31: MTNTU146L USB DB | F31: =2.64/C31/1.13 -> 0.34171174 | G31: 0.41005409 | H31: 0.4510595 | I31: 3.4658618 | J31: =I31*1.05 -> 3.6391548 | K31: =3.14/C31 -> 0.45926576 | L31: =SUBTOTAL(109,H31,J31,K31) -> 4.5494801 | M31: 3.1507834 | N31: ALC269Q-VC3-GR,,RTL8111H-CG
B32: 20240802 | C32: 6.837 | D32: A.P.10000661-MP | E32: A.P.10000661 USB DB | F32: 0.60677268 | G32: 0.72812721 | H32: 0.80093993 | I32: 0.71857295 | J32: =I32*1.05 -> 0.7545016 | K32: 0.2 | L32: =SUBTOTAL(109,H32,J32,K32) -> 1.7554415 | M32: 0.65324814
C33: 6.837 | E33: A.F.D.2300010 | F33: 0.25779335 | G33: 0.30935202 | H33: 0.34028723 | I33: 1.0896289 | J33: =I33*1.05 -> 1.1441104 | K33: 0.2 | L33: =SUBTOTAL(109,H33,J33,K33) -> 1.6843976 | M33: 0.99057176
C34: 6.837 | E34: A.F.D.2300185 DP13_133M_5G_DB | F34: 0.36967638 | G34: 0.44361166 | H34: 0.48797282 | I34: 1.5691934 | J34: =I34*1.05 -> 1.6476531 | K34: 0.2 | L34: =SUBTOTAL(109,H34,J34,K34) -> 2.3356259 | M34: 1.4265394
C35: 6.837 | E35: A.F.D.2300065 133M_DB | F35: 1.6346313 | G35: 1.9615576 | H35: 2.1577133 | I35: 2.2584353 | J35: =I35*1.05 -> 2.3713571 | K35: 0.2 | L35: =SUBTOTAL(109,H35,J35,K35) -> 4.7290704 | M35: 2.053123
C36: 6.837 | E36: A.P.10001140 133H-LHCX-IO_DB | F36: 0.17002527 | G36: 0.20403033 | H36: 0.22443336 | I36: 0.96689736 | J36: =I36*1.05 -> 1.0152422 | K36: 0.2 | L36: =SUBTOTAL(109,H36,J36,K36) -> 1.4396756 | M36: 0.8789976
C37: 6.837 | E37: A.P.10001141 133H-LHCX-LCD_DB | F37: 0.085012636 | G37: 0.10201516 | H37: 0.11221668 | I37: 4.0632777 | J37: =I37*1.05 -> 4.2664416 | K37: 0.2 | L37: =SUBTOTAL(109,H37,J37,K37) -> 4.5786583 | M37: 3.6938888
B38: 20250425 | C38: 6.837 | D38: A.F.D.2500084-MP | E38: A.F.D.2500084 Hall DB | F38: 0.20437267 | G38: 0.24524721 | H38: 0.26977193 | I38: 1.0900664 | J38: =I38*1.05 -> 1.1445698 | K38: 0.2 | L38: =SUBTOTAL(109,H38,J38,K38) -> 1.6143417 | M38: 0.9909695 | N38: ALC269Q
B39: 20240814 | C39: 6.837 | E39: A.F.D.2300276 USB DB | F39: 0.19147823 | G39: 0.22977388 | H39: 0.25275127 | I39: 1.2057698 | J39: =I39*1.05 -> 1.2660583 | K39: 0.2 | L39: =SUBTOTAL(109,H39,J39,K39) -> 1.7188095 | M39: 1.0961543 | N39: 含有ALC269Q
C40: 6.837 | E40: A.F.D.2400033 IO_DB | F40: 0.33097367 | G40: 0.39716841 | H40: 0.43688525 | I40: 1.2015752 | J40: =I40*1.05 -> 1.2616539 | K40: 0.2 | L40: =SUBTOTAL(109,H40,J40,K40) -> 1.8985392 | M40: 1.092341
...

Sheet DB小板汇总 (2)
B1: 12月份汇率：7.01币种:USA | M1: R02
A2: 厂区 | C2: 日期 | D2: 原汇率 | E2: 更新汇率 | F2: 料号 | G2: SKU | H2: PCB | I2: Others | J2: SMT | K2: TTL | L2: 备注
C3: 20250113 | D3: 7.3 | E3: 7.17 | F3: A.F.D.2400329-PVT | G3: A.F.D.2400329 RJ45 DB | H3: 0.69307483 | I3: 2.9511529 | J3: 0.4 | K3: =SUM(H3:J3)+1 -> 5.0442278 | L3: 含RTL8111H；含GL850G；PS8719ETQFN24GTR2-A0
C4: 20250114 | D4: 7.3 | E4: 7.17 | F4: A.F.D.2500004-PVT | G4: A.F.D.2500004 RJ45 DB | H4: 0.41400792 | I4: 2.3394799 | J4: 0.4 | K4: =SUM(H4:J4)+1 -> 4.1534878 | L4: 含RTL8111H；含GL850G；RTS5170
B5: XN21 | C5: 20241113 | D5: 7.2 | E5: 7.17 | F5: A.F.D.2300285-EVT | G5: A.F.D.2300285 RJ45 DB | H5: 0.42621852 | I5: 2.3974685 | J5: 0.4 | K5: =SUM(H5:J5) -> 3.223687 | L5: 含有8111H | M5: .
C6: 20240105 | D6: 7.2 | E6: 7.17 | F6: A.P.10001018 | G6: A.P.10001018 RJ45 DB | H6: 0.71729625 | I6: 2.958558 | J6: 0.4 | K6: =SUM(H6:J6) -> 4.0758542 | L6: 8111H | M6: .
C7: 20241105 | D7: 7.11 | E7: 7.17 | F7: A.F.D.2400048-MP | G7: A.F.D.2400048 USB DB | H7: 0.17305155 | I7: 1.5255259 | J7: 0.2 | K7: =SUM(H7:J7) -> 1.8985775 | L7: 含有IT66318FN
C8: 20240411 | D8: 7.23 | E8: 7.17 | F8: A.F.D.2400049-MP | G8: A.F.D.2400049 USB DB | H8: 0.15624054 | I8: 0.58593119 | J8: 0.2 | K8: =SUM(H8:J8) -> 0.94217173
C9: 20240411 | D9: 7.23 | E9: A.F.M.2401621-MP | F9: A.F.D.2400058-MP | G9: A.F.D.2400058 TYPEC_DB | H9: 0.3252303 | I9: 2.4074114 | J9: 0.3 | K9: =SUM(H9:J9) -> 3.0326418 | L9: 含有ALC269Q
C10: 20240411 | D10: 7.23 | E10: A.F.M.2401623-MP | F10: A.F.D.2400080-MP | G10: A.F.D.2400080 TYPEC_DB | H10: 0.3252303 | I10: 2.8869763 | J10: 0.3 | K10: =SUM(H10:J10) -> 3.5122066 | L10: 含有ALC269Q
C11: 20241105 | D11: 7.11 | E11: 7.17 | F11: A.F.D.2300338-MP | G11: A.F.D.2300338 140M_SS_TYPEC_DB | H11: 0.33630119 | I11: 3.0476113 | J11: 0.4 | K11: =SUM(H11:J11) -> 3.7839125 | M11: .
G12: A.F.D.2300198 140M_2USB_HDMI_DB | H12: 0.1539401 | I12: 1.4743058 | J12: 0.2 | K12: =SUM(H12:J12) -> 1.8282459 | M12: .
G13: A.F.D.2300246 140M_SS_TYPEC_DB | H13: 0.41368268 | I13: 3.1707387 | J13: 0.4 | K13: =SUM(H13:J13) -> 3.9844214 | M13: .
G14: A.F.D.2300339 140M-SS_DB | H14: 0.1539401 | I14: 1.5132013 | J14: 0.2 | K14: =SUM(H14:J14) -> 1.8671414 | M14: .
C15: 20240914 | D15: 7.11 | E15: 7.17 | F15: A.F.D.2400234-PVT | G15: A.F.D.2400234 TYPEC DB | H15: 0.44288165 | I15: 1.3448892 | J15: 0.2 | K15: =SUM(H15:J15) -> 1.9877709 | L15: 含有SN6140
C16: 20250114 | D16: 7.3 | E16: 7.17 | F16: A.F.D.2400198-MP | G16: A.F.D.2400198 RJ45 DB | H16: 0.58215771 | I16: 3.5789941 | J16: 0.4 | K16: =SUM(H16:J16) -> 4.5611518 | L16: 含有RTL8111H；ALC269Q；OZ711LV2
G17: A.F.D.2400171 RJ45 DB | H17: 0.52283876 | I17: 3.6582337 | J17: 0.4 | K17: =SUM(H17:J17) -> 4.5810725 | L17: 含有8111H;ALC269Q
B18: DN50Z | C18: 20240625 | D18: 7.26 | E18: 7.17 | F18: A.F.D.2300323-MP | G18: A.F.D.2300323 USB DB | H18: 0.37756201 | I18: 2.7131335 | J18: 0.2 | K18: =SUM(H18:J18) -> 3.2906955
C19: 20241030 | D19: 7.11 | E19: 7.17 | F19: A.F.D.2300239-MP | G19: A.F.D.2300239 RJ45 DB | H19: 0.58161235 | I19: 6.9714999 | J19: 0.4 | K19: =SUM(H19:J19) -> 7.9531122 | L19: 含INTEL网卡ic-I226LM_SRKTT；ALC269Q；FG24102SEG（后期换料）
C20: 20241030 | D20: 7.11 | E20: 7.17 | F20: A.F.D.2300240-MP | G20: A.F.D.2300240 RJ45 DB | H20: 0.58161235 | I20: 4.9677094 | J20: 0.4 | K20: =SUM(H20:J20) -> 5.9493218 | L20: 含INTEL网卡ic-I226V_SRKTV；ALC269Q；FG24102SEG（后期换料）
B21: DN50Z | C21: 2025 0226 | D21: 7.25 | E21: 7.17 | F21: A.F.D.2300324-MP | G21: A.F.D.2300324 USB DB | H21: 0.37912649 | I21: 3.0004157 | J21: 0.2 | K21: =SUM(H21:J21) -> 3.5795421 | L21: ALC269Q
G22: A.P.10001155 140HC_YD_DB | H22: 0.42207473 | I22: 2.8826944 | J22: 0.4 | K22: =SUM(H22:J22) -> 3.7047692
G23: A.P.10001028 RJ45 DB | H23: 0.7575 | I23: 4.1309 | J23: 0.8 | K23: =SUM(H23:J23) -> 5.6884 | L23: I219V，ALC269
G24: A.P.10001065 4G USB DB | H24: 0.54729064 | I24: 3.6663 | J24: 0.4 | K24: =SUM(H24:J24) -> 4.6135906
G25: A.P.10001028 RJ45 DB | H25: 0.7575 | I25: 4.1309 | J25: 0.4 | K25: =SUM(H25:J25) -> 5.2884 | L25: I219V，ALC269
C26: 46105 | D26: 6.91
C27: 46105 | D27: 6.91
C28: 20240312 | D28: 7.2 | E28: A.F.M.2401762 | F28: A.F.D.2300211-MP | G28: A.F.D.2300211 RJ45 DB | H28: 0.56716292 | I28: 4.015214 | J28: 0.4 | K28: =SUM(H28:J28) -> 4.9823769 | L28: 含有Intel WGI219V;ALC269Q | P28: =42.7/D28/1.13 -> 5.2482793 | Q28: 28.5
C29: 20241115 | D29: 7.2 | E29: 7.17 | F29: A.F.D.2300380-PVT | G29: A.F.D.2300380 USB DB | H29: 0.44112671 | I29: 2.2778284 | J29: 0.2 | K29: =SUM(H29:J29) -> 2.9189551 | L29: ALC269Q-VC3-GR;PS8719ETQFN24GTR2;RTS5170-GR
B30: XN32G | G30: A.F.D.2300283 RJ45 DB | H30: 0.42544642 | I30: 3.0663503 | J30: 0.4 | K30: =SUM(H30:J30) -> 3.8917967
C31: 20250715 | E31: 7.17 | F31: A.P.10001066 | G31: A.P.10001066 AUDIO DB | H31: 6.8649733 | I31: 1.6074609 | J31: 0.2 | K31: =SUM(H31:J31) -> 8.6724342 | L31: 含在主板BOM里面的 需合计
C32: 20250218 | D32: 7.3 | E32: 7.17 | F32: A.F.D.2300201-MP | G32: A.F.D.2300201 AUDIO DB | H32: 0.33973003 | I32: 1.6271865 | J32: 0.2 | K32: =SUM(H32:J32) -> 2.1669165 | L32: SN6140；RTS5170；PS8719ETQFN24GTR2-A0
C33: 20250807 | D33: 7.17 | E33: 7.17 | F33: A.F.D.2500222-PVT | G33: A.F.D.2500222 RJ45 DB | H33: 0.48143321 | I33: 2.9314622 | J33: 0.4 | K33: =SUM(H33:J33) -> 3.8128955 | L33: 含8111H、ALC269Q
C34: 20240829 | D34: 7.12 | E34: 7.17 | F34: A.F.D.2400221-EVT | G34: A.F.D.2400221 RJ45 DB | H34: 0.48718299 | I34: 2.7628105 | J34: 0.4 | K34: =SUM(H34:J34) -> 3.6499935 | L34: 含8111H
B35: DA1059E | C35: 20250516 | D35: 7.19 | G35: A.F.D.2300379 RJ45 DB | H35: 0.43875436 | I35: 3.2950853 | J35: 0.4 | K35: =SUM(H35:J35) -> 4.1338397 | L35: 含8111H、ALC269Q
C36: 20240802 | D36: 7.26 | E36: 7.17 | F36: A.P.10000661-MP | G36: A.P.10000661 USB DB | H36: 0.59172014 | I36: 0.64271927 | J36: 0.2 | K36: =SUM(H36:J36) -> 1.4344394 | Q36: 16 | V36: TYPE-C:ANX7447QN-AC-R,电量计:CW2217,视频桥接：IT6113FN
G37: A.F.D.2300010 | H37: 0.25139813 | I37: 0.97460601 | J37: 0.2 | K37: =SUM(H37:J37) -> 1.4260041
G38: A.F.D.2300185 DP13_133M_5G_DB | H38: 0.36050562 | I38: 1.4035469 | J38: 0.2 | K38: =SUM(H38:J38) -> 1.9640525
G39: A.F.D.2300065 133M_DB | H39: 1.5940801 | I39: 2.0200314 | J39: 0.2 | K39: =SUM(H39:J39) -> 3.8141115
G40: A.P.10001140 133H-LHCX-IO_DB | H40: 0.16580736 | I40: 0.86483017 | J40: 0.2 | K40: =SUM(H40:J40) -> 1.2306375
...

Sheet E BOM大核
C1: 9月汇率：6.71 | U1: pcb为普通材质OSP工艺，如用特殊材质请单独核;CPU;DDR;SSD;EMMC;WIFI请按需求选配, | W1: - | X1: 类型 | Y1: 型号 | Z1: 美金单项单价 | AB1: - | AC1: 类型 | AD1: 型号 | AE1: 美金单项单价 | AG1: 类型 | AH1: 型号 | AI1: 美金单项单价
W2: - | X2: TYPC IC | Y2: ANX7447QN | Z2: 0.64 | AB2: - | AC2: 加密IC TPM | AD2: 9672 | AE2: 1.05 | AG2: HDMI2.0 | AH2: IT66318FN | AI2: 0.71
W3: - | Y3: CYPD6228 | Z3: 1.7769148 | AB3: - | AI3: =0.48*1.05 -> 0.504
AG4: HDMI2.1 | AH4: ANX7484Q42 | AI4: 0.94
I5: 币种：USD | W5: - | Y5: CYPD6227 | Z5: 1.8079 | AB5: - | AC5: 电量计 | AD5: CW2217 | AE5: 0.23 | AG5: USB3-10G | AH5: GL9901VAE | AI5: 0.37
Y6: CS32G053HRCW6NR/ANX7484Q42 | Z6: 0.99 | AH6: PS8811QFN36 | AI6: =0.9*1.05 -> 0.945
W7: - | Y7: ASL2330AN | Z7: 0.52 | AB7: - | AC7: 雷电IC | AD7: 8040 | AE7: 2.948 | AG7: OLED | AH7: G2708CKU1U | AI7: 2.36
Y8: IT8856FN/CX | Z8: 0.93 | AD8: 9040 | AE8: 3.054
C9: 机型 | D9: PCB尺寸 | E9: 日期 | F9: 汇率 | G9: 料号 | H9: SKU | I9: TPYE-C | J9: 功率 | K9: WIFI | L9: CPU/存储 | M9: WIFI | N9: PCB | O9: PCB | P9: Others | Q9: SMT | R9: TTL | T9: DDR/SSD | U9: 包含可选功能 | V9: 备注 | Y9: IT5272FN | Z9: 1
A10: 3 | B10: 46246 | C10: DN21C(8L+通孔+OSP) | D10: 214.5*120.0*1.0mm | E10: 20240919 | F10: 6.75 | G10: A.F.M.2401621-MP | H10: SKU135 | I10: 单Tpye c IC及双Type c接口（ANX7447QN） | J10: U-15W | K10: 选配 | L10: 现询 | M10: 选配 | N10: 4.77 | O10: =45.18/F10/1.13*1.05 -> 6.219469 | P10: 18.53 | Q10: =24.03/F10/1.13 -> 3.1504425 | R10: =SUBTOTAL(109,O10:Q10) -> 27.899912 | S10: 16.4 | T10: 条子/SSD PCIE3.0 | U10: TPM TPM(9672)； 电量计：CW2217; ROM:128Mb;
A11: 2 | B11: 46246 | D11: 214.5*120.0*1.0mm | E11: 20240919 | F11: 6.75 | G11: A.F.M.2401623-MP | H11: SKU137 | I11: 单Tpye c IC及双Type c接口（ANX7447QN） | J11: H-28W | K11: 选配 | L11: 现询 | M11: 选配 | N11: 4.77 | O11: =45.18/F11/1.13*1.05 -> 6.219469 | P11: 20.2 | Q11: =24.03/F11/1.13 -> 3.1504425 | R11: =SUBTOTAL(109,O11:Q11) -> 29.569912 | S11: 18 | T11: 条子/SSD PCIE3.0 | U11: TPM TPM(9672)； 电量计：CW2217; ROM:128Mb;
A12: 3 | C12: DN25(10L+通孔+OSP) | D12: 188.1*99.2 | E12: 20250827 | F12: 6.75 | G12: A.F.M.2509998 | H12: SKU99 | I12: 单Tpye c IC及双Type c接口（CYPD6227） | J12: U-15W | K12: 选配 | L12: 现询 | M12: 选配 | N12: 4.9455492 | O12: 5.4401041 | P12: 27.4 | Q12: 3.1167329 | R12: =SUBTOTAL(109,O12:Q12) -> 35.956837 | S12: 24.3 | T12: LPDDR5-315球8G*4 | U12: 雷电IC8040; HDMI2.0 IT66318FN； TPM TPM(9672)；电量计： CW2217
A13: 3 | D13: 188.1*99.2 | E13: 20250827 | F13: 6.75 | G13: A.F.M.2509999 | H13: SKU100 | I13: 单Tpye c IC及双Type c接口（CYPD6227） | J13: H-28W | K13: 选配 | L13: 现询 | M13: 选配 | N13: 4.9455492 | O13: 5.4401041 | P13: 29.2 | Q13: 3.1167329 | R13: =SUBTOTAL(109,O13:Q13) -> 37.756837 | S13: 25.95 | T13: LPDDR5-315球8G*4 | U13: 雷电IC8040; HDMI2.0, IT66318FN； TPM TPM(9672)； 电量计：CW2217
A14: 3 | C14: DN79(8L++通孔+OSP) | D14: 237.8*138.1 | E14: 20250827 | F14: 6.7 | G14: A.F.M.2501814 | H14: SKU27 | I14: 单Tpye c IC及双Type c接口（CYPD6227） | J14: U-15W | K14: 选配 | L14: 现询 | M14: 选配 | N14: 6.1542946 | O14: =56.43/F14/1.13*1.05 -> 7.8261128 | P14: 24.4 | Q14: =24.1707/F14/1.13 -> 3.1925373 | R14: =SUBTOTAL(109,O14:Q14) -> 35.41865 | S14: 21.9 | T14: 条子 | U14: 雷电IC8040； HDMI2.0 IT66318FN; TPM TPM(9672) ; USB3-10G GL9901VAE-OGY11 电量计CW2217： ROM:128Mb;
A15: 3 | D15: 237.8*138.1 | E15: 20250827 | F15: 6.7 | G15: A.F.M.2501815 | H15: SKU28/SKU29 | I15: 单Tpye c IC及双Type c接口（CYPD6227） | J15: P/H-28W/45W | K15: 选配 | L15: 现询 | M15: 选配 | N15: 6.1542946 | O15: =56.43/F15/1.13*1.05 -> 7.8261128 | P15: 26.1 | Q15: =24.1707/F15/1.13 -> 3.1925373 | R15: =SUBTOTAL(109,O15:Q15) -> 37.11865 | S15: 23.5 | T15: 条子 | U15: 雷电IC8040； HDMI2.0 IT66318FN; TPM TPM(9672) ; USB3-10G GL9901VAE-OGY11 电量计CW2217； ROM:128Mb;
A16: 3 | C16: MTN25C(10L++通孔+OSP) | D16: 188.1*99.2阴阳铜 | E16: 20250829 | F16: 6.75 | G16: A.F.M.2509000 | H16: SKU99 | I16: 双Type C IC及双Type C 接口（ANX7447QN） | J16: U-15W | K16: 选配 | L16: 现询 | M16: 选配 | N16: =30.8/6.78/1.13*1.4 -> 5.6282142 | O16: =39.2/F16/1.13*1.05 -> 5.3962635 | P16: 24.5 | Q16: =23.91/F16/1.13 -> 3.1347099 | R16: =SUBTOTAL(109,O16:Q16) -> 33.030973 | S16: 21.95 | T16: LPDDR5x-315球4G*4 | U16: TPM TPM(9672)； 电量计：CW2217;； HDMI2.0 IT66318FN; ROM；256Mb
A17: 3 | D17: 188.1*99.2阴阳铜 | E17: 20250829 | F17: 6.75 | G17: A.F.M.2509001 | H17: SKU100 | I17: 双Type C IC及双Type C 接口（ANX7447QN） | J17: H-28W | K17: 选配 | L17: 现询 | M17: 选配 | N17: =30.8/6.78/1.13*1.4 -> 5.6282142 | O17: =39.2/F17/1.13*1.05 -> 5.3962635 | P17: 26.1 | Q17: =23.91/F17/1.13 -> 3.1347099 | R17: =SUBTOTAL(109,O17:Q17) -> 34.630973 | S17: 23.4 | T17: LPDDR5x-315球4G*4 | U17: TPM TPM(9672)； 电量计：CW2217;； HDMI2.0 IT66318FN ROM；256Mb
A18: 3 | C18: MTN25(10L+通孔+OSP) | D18: 188.1*99.2*1.0mm | E18: 20250904 | F18: 6.75 | G18: A.F.M.2900100 | I18: 单Type C IC及两个Type C 接口（CYPD6228） | J18: U-15W | K18: BE200 | L18: 现询 | M18: 现询 | N18: 4.8056225 | O18: 5.2861848 | P18: 30.4 | Q18: =24.86/F18/1.13 -> 3.2592593 | R18: =SUBTOTAL(109,O18:Q18) -> 38.945444 | S18: 27.4 | T18: LPDDR5-315球8G*4 | U18: OLED:G2708CKU1U; 含加密IC TPM(9672)；雷电IC9040;含CW2217; HDMI2.0 :IT66318FN; 降噪钽电
A19: 3 | D19: 188.1*99.2*1.0 | E19: 20250904 | F19: 6.75 | G19: A.F.M.2900101 | I19: 单Tpye c IC及两个Type c接口（CYPD6228） | J19: H-28W | K19: BE200 | L19: 现询 | M19: 现询 | N19: 4.8056225 | O19: 5.2861848 | P19: 32.25 | Q19: =24.86/F19/1.13 -> 3.2592593 | R19: =SUBTOTAL(109,O19:Q19) -> 40.795444 | S19: 29.3 | T19: LPDDR5-315球8G*4 | U19: OLED:G2708CKU1U; 含加密IC TPM(9672)；雷电IC9040;含CW2217: HDMI2.0: IT66318FN；降噪钽电
A20: 3 | C20: DN25C(10L++通孔+OSP) | D20: 188.1*99.2 | E20: 46080 | F20: 6.72 | G20: 全配 | H20: SKU99 | I20: 双Type C IC及双Type C 接口（ANX7447QN） | J20: U-15W | K20: AX101.D2WG.NV | L20: 现询 | M20: - | N20: 4.0104112 | O20: =39.2/F20/1.13*1.05 -> 5.420354 | P20: 26.3 | Q20: =23.3/F20/1.13 -> 3.0683734 | R20: =SUBTOTAL(109,O20:Q20) -> 34.788727 | S20: 21.5 | T20: LPDDR5-315球8G*4 | U20: HDMI2.0:IT66318FN/; TPM: SLB 9672;: 电量计：CW2217: ROM:128Mb
A21: 3 | D21: 188.1*99.2 | E21: 46080 | F21: 6.72 | G21: A.F.M.2510000 | H21: SKU100 | I21: 双Type C IC及双Type C 接口（ANX7447QN） | J21: H-28W | K21: AX101.D2WG.NV | L21: 现询 | M21: - | N21: 4.0104112 | O21: =39.2/F21/1.13*1.05 -> 5.420354 | P21: 28.3 | Q21: =23.3/F21/1.13 -> 3.0683734 | R21: =SUBTOTAL(109,O21:Q21) -> 36.788727 | S21: 23.2 | T21: LPDDR5-315球8G*4 | U21: HDMI2.0:IT66318FN/; TPM: SLB 9672;: 电量计：CW2217: ROM:128Mb
A22: 3 | C22: DP67(10L++通孔+OSP) | D22: 214*88*0.8 | E22: 20250901 | F22: 6.75 | G22: A.F.M.2501282 | H22: SKU19 | I22: 单Type-c IC及双Type c 接口(CYPD6227) | J22: U-15W | K22: 选配 | L22: 现询 | M22: 选配 | N22: 4.9433628 | O22: 5.4376991 | P22: 18.2 | Q22: =22.95/F22/1.13 -> 3.0088496 | R22: =SUBTOTAL(109,O22:Q22) -> 26.646549 | S22: 15.55 | T22: LPDDR4x-200球4GB*4 | U22: 电量计 ：CW2217; ROM:128Mb
A23: 3 | C23: DP67C（10L++通孔+OSP) | D23: 214*88 | E23: 20250805 | F23: 6.75 | G23: A.F.M.2501922-EVT | H23: SKU1 | I23: Type c(双Type c接口)(CYPD6227) | J23: U-15W | K23: AX211.D2WG | L23: 现询 | M23: - | N23: 4.9433628 | O23: 5.4376991 | P23: 18.1 | Q23: 4.1796878 | R23: =SUBTOTAL(109,O23:Q23) -> 27.717387 | S23: 15.6 | T23: LPDDR5X-315球4G*4+0 | U23: 电量计 ：CW2217; ROM:128Mb
A24: 2 | D24: 214*88 | E24: 20250805 | F24: 6.75 | G24: A.F.M.2503368 | H24: SKU6 | I24: Type c(双Type c接口)(CYPD6227) | J24: U-15W | K24: 选配 | L24: 现询 | M24: 选配 | N24: 4.9433628 | O24: 5.4376991 | P24: 18.3 | Q24: 4.1796878 | R24: =SUBTOTAL(109,O24:Q24) -> 27.917387 | S24: 15.9 | T24: LPDDR5X-315球4G*4+0 | U24: 电量计 ：CW2217; ROM:128Mb
A25: 3 | B25: 46251 | C25: DN21F(8L++通孔+OSP) | D25: 214.5*120 | E25: 46157 | F25: 6.75 | G25: A.F.M.2401749 | H25: SKU6 | I25: 单Type C IC及单Type C 接口（ANX7447QN） | J25: H-28W | K25: 选配 | L25: 现询 | M25: 选配 | N25: 4.8771473 | O25: =40.125/F25/1.13*1.05 -> 5.5235988 | P25: 17.34 | Q25: =22.56/F25/1.13 -> 2.9577188 | R25: =SUBTOTAL(109,O25:Q25) -> 25.821318 | S25: 15.5 | T25: 条子 | U25: HDMI2.0:IT66318FN; TPM: SLB 9672V 电量计 ：CW2217; ROM:128Mb
A26: 3 | B26: 46251 | D26: 214.5*120 | E26: 20250903 | F26: 6.75 | G26: A.F.M.2501634 | H26: SKU19 | I26: 单Type C IC及单Type C 接口（ANX7447QN） | J26: U-15W | K26: 选配 | L26: 现询 | M26: 选配 | N26: 4.8771473 | O26: =40.125/F26/1.13*1.05 -> 5.5235988 | P26: 15.74 | Q26: =22.56/F26/1.13 -> 2.9577188 | R26: =SUBTOTAL(109,O26:Q26) -> 24.221318 | S26: 13.5 | T26: 条子 | U26: HDMI2.0:IT66318FN; 电量计 ：CW2217; ROM:128Mb
A27: 3 | B27: 46252 | C27: MTN50(8L+HDI+沉金) | D27: 230.7*120.8 | E27: 20260106 | F27: 6.75 | G27: A.F.M.2401762 | H27: SKU12 | I27: 单Tpye c IC及双Type c接口（RTS5453H） | J27: U-28W | K27: 选配 | L27: 现询 | M27: 选配 | N27: 7.2228006 | O27: =63.81/F27/1.13*1.05 -> 8.7840708 | P27: 32.1 | Q27: =24.12/F27 -> 3.5733333 | R27: =SUBTOTAL(109,O27:Q27) -> 44.457404 | S27: 29.4 | T27: 条子 | U27: 雷电JHL9040R*2； HDMI2.1 ANX7484Q42； TPM:SLB 9672VU; USB3-10G GL9901VAE
A28: 3 | C28: MTN79(8L++通孔+OSP) | D28: 237.8*138.1 | E28: 46151 | F28: 6.7 | G28: A.F.M.2501824 | H28: SKU24 | I28: 单Type C IC及双Type c接口（CYPD6228） | J28: U-15W | K28: 选配 | L28: 现询 | M28: 选配 | N28: 6.1717855 | O28: =56.43/F28/1.13*1.05 -> 7.8261128 | P28: 25.4 | Q28: 3.6572268 | R28: =SUBTOTAL(109,O28:Q28) -> 36.88334 | S28: 22 | T28: 条子 | U28: 电量计CW2217;HDMI2.0 IT66318FN; TPM:SLB 9672; USB3-10G GL9901VAE
A29: 3 | D29: 237.8*138.1 | E29: 46151 | F29: 6.7 | G29: A.F.M.2501825 | H29: SKU25 | I29: 单Type C IC及双Type c接口（CYPD6228） | J29: H-28W | K29: 选配 | L29: 现询 | M29: 选配 | N29: 6.1717855 | O29: =56.43/F29/1.13*1.05 -> 7.8261128 | P29: 29.4 | Q29: 3.6572268 | R29: =SUBTOTAL(109,O29:Q29) -> 40.88334 | S29: 24.3 | T29: 条子 | U29: 电量计CW2217;HDMI2.0 IT66318FN; TPM:SLB 9672; USB3-10G GL9901VAE
A30: 3 | D30: 237.8*138.1 | E30: 46151 | F30: 6.7 | G30: A.F.M.2501826 | H30: SKU26 | I30: 单Type C IC及双Type c接口（CYPD6228） | J30: H-45W | K30: 选配 | L30: 现询 | M30: 选配 | N30: 6.1717855 | O30: =56.43/F30/1.13*1.05 -> 7.8261128 | P30: 30.1 | Q30: 3.6572268 | R30: =SUBTOTAL(109,O30:Q30) -> 41.58334 | S30: 25 | T30: 条子 | U30: 电量计CW2217;HDMI2.0 IT66318FN; TPM:SLB 9672; USB3-10G GL9901VAE
A31: 3 | C31: DN79C(8L++通孔+OSP) | D31: 237.8*138.1 | E31: 20250908 | F31: 6.7 | G31: 全配 | H31: SKU47 | I31: 单Type C IC及双Type C 接口（CYPD6228） | J31: U-15W | K31: 选配 | L31: 现询 | M31: 选配 | N31: 6.3329047 | O31: =56.43/F31/1.13*1.05 -> 7.8261128 | P31: 22.3 | Q31: 3.2876639 | R31: =SUBTOTAL(109,O31:Q31) -> 33.413777 | S31: 19.6 | T31: 条子 | U31: TPM 9672; HDMI2.0 IT66318FN; USB 3-10G GL9901V ;电量计:CW2217;ROM;128Mb
A32: 3 | D32: 237.8*138.1 | E32: 20250908 | F32: 6.7 | G32: 全配 | H32: SKU48/SKU49 | I32: 单Type C IC及双Type C 接口（CYPD6228） | J32: H-28W/45W | K32: 选配 | L32: 现询 | M32: 选配 | N32: 6.3329047 | O32: =56.43/F32/1.13*1.05 -> 7.8261128 | P32: 24.2 | Q32: 3.2876639 | R32: =SUBTOTAL(109,O32:Q32) -> 35.313777 | S32: 21.4 | T32: 条子 | U32: TPM 9672; HDMI2.0 IT66318FN; USB 3-10G GL9901V ;电量计:CW2217;ROM;128Mb
A33: 3 | C33: DN50F(8L++通孔+OSP) | D33: 229.55*122.86 | E33: 202509090 | F33: 6.75 | G33: A.F.M.2400375 | H33: SKU5 | I33: 双Typc c及双Type c 接口(IT8856FN/CX) | J33: P-28W | K33: 选配 | L33: 现询 | M33: 选配 | N33: 6.7730349 | O33: 7.4503384 | P33: 31.08 | Q33: =25.99/F33/1.13 -> 3.4074074 | R33: =SUBTOTAL(109,O33:Q33) -> 41.937746 | S33: 27.9 | T33: 条子 | U33: 雷电JHL9040R*2； HDMI2.0 IT66318FN； TPM:SLB 9672VU; USB3.1-10G PS8811QFN36GTR2
A34: 3 | C34: DN50F(8L++通孔+OSP) | D34: 229.55*122.86 | E34: 46112 | F34: 6.75 | G34: A.F.M.2600626 | H34: SKU19 | I34: 双Typc c及双Type c 接口(IT8856FN/CX) | J34: U-15W | K34: 选配 | L34: 现询 | M34: 选配 | N34: 6.707444 | O34: 7.3781884 | P34: 32.35 | Q34: =25.99/F34/1.13 -> 3.4074074 | R34: =SUBTOTAL(109,O34:Q34) -> 43.135596 | S34: 25.53 | T34: 条子 | U34: 雷电JHL8040R*2； HDMI2.0 IT66318FN; USB3-10G :PS8811QFN36
A35: 3 | C35: DNTU146F(8L+通孔++OSP) | D35: 234.77*117.04 | E35: 20250915 | F35: 6.75 | G35: A.F.M.2502116 | H35: SKU1 | I35: 单Type c及含双Type c接口(ASL2330AN) | J35: U-15W | K35: CDW-61822CE | L35: 现询 | M35: - | N35: =40.94/6.78/1.13*1.05 -> 5.6108544 | O35: =51.63/6.73/1.13*1.05 -> 7.1284961 | P35: 15.2 | Q35: =21.2/F35/1.13 -> 2.7794166 | R35: =SUBTOTAL(109,O35:Q35) -> 25.107913 | S35: 13.03 | T35: 条子 | U35: 电量计：CW2217, ROM:128Mb
A36: 3 | D36: 234.77*117.04 | E36: 20250915 | F36: 6.75 | G36: A.F.M.2502117 | H36: SKU2 | I36: 双Type c及含双Type c接口(ANX7447QN) | J36: H-45W | K36: CDW-61852BE | L36: 现询 | M36: - | N36: =40.94/6.78/1.13*1.05 -> 5.6108544 | O36: =51.63/6.73/1.13*1.05 -> 7.1284961 | P36: 19.2 | Q36: =21.2/F36/1.13 -> 2.7794166 | R36: =SUBTOTAL(109,O36:Q36) -> 29.107913 | S36: 16.77 | T36: 条子 | U36: 电量计：CW2217, ROM:128Mb
A37: 3 | C37: DNTU146A(8L++通孔+OSP) | D37: 234.7*127.2 | E37: 20250825 | F37: 6.75 | G37: A.F.M.2502045-EVT | H37: SKU1 | I37: 双Type c及含双Type c接口((ANX7447QN)) | J37: U-15W | K37: WD_RTL8821CE | L37: 现询 | M37: - | N37: 5.9968766 | O37: =55.99/6.73/1.13*1.05 -> 7.7304764 | P37: 15 | Q37: =21.95/F37/1.13 -> 2.877745 | R37: =SUBTOTAL(109,O37:Q37) -> 25.608221 | S37: 12.76 | T37: 条子 | U37: 电量计：CW2217, ROM:128Mb
A38: 3 | D38: 234.7*127.2 | E38: 20250825 | F38: 6.75 | G38: A.F.M.2502046-EVT | H38: SKU2 | I38: 双Type c及含双Type c接口(ASL2330AN) | J38: H-28W | K38: CDW-61821CE | L38: 现询 | M38: - | N38: 5.9968766 | O38: =55.99/6.73/1.13*1.05 -> 7.7304764 | P38: 17.1 | Q38: =21.95/F38/1.13 -> 2.877745 | R38: =SUBTOTAL(109,O38:Q38) -> 27.708221 | S38: 14.73 | T38: 条子 | U38: 电量计：CW2217, ROM:128Mb
A39: 3 | D39: 234.7*127.2 | E39: 20250825 | F39: 6.75 | G39: A.F.M.2502047-EVT | H39: SKU3 | I39: 双Type c及含双Type c接口((ANX7447QN)) | J39: H-45W | K39: CDW-61822CE | L39: 现询 | M39: - | N39: 5.9968766 | O39: =55.99/6.73/1.13*1.05 -> 7.7304764 | P39: 17.3 | Q39: =21.95/F39/1.13 -> 2.877745 | R39: =SUBTOTAL(109,O39:Q39) -> 27.908221 | S39: 14.94 | T39: 条子 | U39: 电量计：CW2217, ROM:128Mb
A40: 3 | B40: 46246 | C40: DNTU146(8L++通孔+OSP) | D40: 234.7*127.2 | E40: 46058 | F40: 6.75 | G40: A.F.M.2501238-EVT | H40: SKU1 | I40: 单Type c及含双Type c接口(ANX7447QN) | J40: U-15W | K40: 61821CE | L40: 现询 | M40: - | N40: 5.5783446 | O40: =55.99/6.73/1.13*1.05 -> 7.7304764 | P40: 15.5 | Q40: =19.63/F40 -> 2.9081481 | R40: =SUBTOTAL(109,O40:Q40) -> 26.138625 | S40: 13.55 | T40: 条子 | U40: 电量计：CW2217, ROM:128Mb
...

Sheet 对比差异
B1: 12月份汇率：7.04币种:USA
B2: 机型 | C2: 功率 | D2: 配置 | E2: Others | F2: PCB | G2: SMT | H2: TTL | I2: 备注 | J2: 差异点
B3: MTNTU146(8L+通孔+OSP) | C3: H-28W | D3: 0+0 | E3: 17.965528 | F3: =35.53/7.04/1.13 -> 4.4662611 | G3: 3 | H3: =SUM(E3:G3) -> 25.431789 | I3: SMT预估 | J3: 两颗DIMM/DDR5座子，两颗7447
B4: MTNTU146B(10L+HDI2+OSP) | C4: H-28W | D4: 0+0 | E4: 16.189418 | F4: =47.32/7.04/1.13 -> 5.9483105 | G4: 3.2 | H4: =SUM(E4:G4) -> 25.337728 | I4: SMT预估 | J4: 单颗7447
D5: 差异 | E5: =E4-E3 -> -1.77611 | F5: =F4-F3 -> 1.4820495 | G5: =G4-G3 -> 0.2 | H5: =H4-H3 -> -0.094060547
B6: MTN21(8L+通孔+OSP) | C6: H-28W | D6: 0+0 | E6: 20.25 | F6: =30.43/7.04/1.13 -> 3.825171 | G6: =25.08/7.04/1.13 -> 3.1526549 | H6: =SUM(E6:G6) -> 27.227826
B7: MTN21B(10L+HDI2+OSP) | C7: H-28W | D7: 0+0 | E7: 20 | F7: =47.63/7.04/1.13 -> 5.9872788 | G7: =27.12/7.04/1.13 -> 3.4090909 | H7: =SUM(E7:G7) -> 29.39637 | I7: SMT预估
D8: 差异 | E8: =E7-E6 -> -0.25 | F8: =F7-F6 -> 2.1621078 | G8: =G7-G6 -> 0.25643604 | H8: =H7-H6 -> 2.1685438
B9: MTN79(8L+通孔+OSP) | C9: H-28W | D9: 0+0 | E9: 21.286257 | F9: =37.8775/7.04/1.13 -> 4.7613511 | G9: 3.5 | H9: =SUM(E9:G9) -> 29.547608 | I9: SMT预估 | J9: 9颗钽电容(15UF)，PD/赛普拉斯6228
B10: MTN793(10L+通孔+OSP) | C10: H-28W | D10: 0+0 | E10: =18.4933180946859 -> 18.493318 | F10: =37.8775/7.04/1.13 -> 4.7613511 | G10: 4 | H10: =SUM(E10:G10) -> 27.254669 | I10: SMT预估 | J10: PD/芯海035H，未加315转接小板
D11: 差异 | E11: =E10-E9 -> -2.7929391 | F11: =F10-F9 -> 0 | G11: =G10-G9 -> 0.5 | H11: =H10-H9 -> -2.2929391
E13: =0.7+1.25 -> 1.95

Sheet E BOM大核 (2)
B1: 汇率：6.75 | R1: pcb为普通材质OSP工艺，如用特殊材质请单独核;CPU;DDR;SSD;EMMC;WIFI请按需求选配 | T1: - | U1: 类型 | V1: 型号 | W1: 美金单项单价 | Y1: - | Z1: 类型 | AA1: 型号 | AB1: 美金单项单价
T2: - | U2: TYPC IC | V2: ANX7447QN | W2: 0.64 | Y2: - | Z2: 加密IC TPM | AA2: 9672 | AB2: 1.05
T3: - | V3: CYPD6228 | W3: 1.7769148 | Y3: - | Z3: 电量计 | AA3: CW2217 | AB3: 0.23
T4: - | V4: CYPD6227 | W4: 1.8079 | Y4: - | Z4: 雷电IC | AA4: 8040 | AB4: 2.948
T5: - | V5: ASL2330AN | W5: 0.52 | Y5: - | AA5: 9040 | AB5: 3.054
V6: IT8856FN/CX | W6: 0.93
A7: 厂区 | B7: 机型 | C7: PCB尺寸 | D7: 日期 | E7: 汇率 | F7: 料号 | G7: SKU | H7: Type c | I7: 功率 | J7: WIFI | K7: DDR 存储 | L7: WIFI | M7: PCB | N7: Others | O7: SMT | P7: TTL | Q7: 备注 | R7: 已含型号备注
A8: 1 | B8: ROBOT临时核价20260104 | D8: 20260104 | E8: 7.01 | F8: A.F.M.2401621-MP | J8: NA | K8: 选配 | L8: NA | M8: =[2]深圳英众PCB单价清单!$P$1014/E8/1.13 -> 3.7241362 | N8: 41.248623 | O8: 3.5 | P8: =SUM(K8:O8) -> 48.472759 | Q8: 条子 | R8: pcb按MTN25机型参考报价，SMT预估，后续正式bom再按实际核价为准,不含keypark报价
A9: 2 | B9: ROBOT临时核价20260105小板 | F9: A.F.M.2401623-MP | J9: NA | K9: NA | L9: NA | M9: 0.6 | N9: 0.48775694 | O9: 0.5 | P9: =SUM(K9:O9) -> 1.5877569 | Q9: 条子 | R9: pcb按xn25预估，smt预估
B10: DNN253 | E10: 6.78 | F10: A.F.M.2602447 | J10: - | K10: 现询 | L10: - | M10: =27.8/E10/1.13 -> 3.6285796 | N10: 14.1 | O10: =22/E10 -> 3.2448378 | P10: =SUM(K10:O10) -> 20.973417 | Q10: 条子 | R10: PCB持续上涨，实单前重新确认
B11: WN38(8L+通孔+OSP) | E11: 6.78 | F11: A.F.M.2400978 | H11: =H9-H10 -> 0 | J11: - | K11: 现询 | L11: - | M11: =58.17/E11/1.13*1.05 -> 7.9722375 | N11: =16.4*1.05 -> 17.22 | O11: =23/E11 -> 3.3923304 | P11: =SUM(K11:O11) -> 28.584568 | Q11: PCB价保一周
B12: WN38(8L+通孔+OSP) | E12: 6.78 | F12: A.F.M.2400991 | J12: - | K12: 现询 | L12: - | M12: =58.17/E12/1.13*1.05 -> 7.9722375 | N12: =16.4*1.05 -> 17.22 | O12: =23/E12 -> 3.3923304 | P12: =SUM(K12:O12) -> 28.584568 | Q12: PCB价保一周
B13: DN105(8L+通孔+OSP) | E13: 6.78 | F13: A.F.M.2501240 | J13: - | K13: 现询 | L13: - | M13: =62.5/E13/1.13 -> 8.157778 | N13: =13.95*1.05 -> 14.6475 | O13: =22/E13 -> 3.2448378 | P13: =SUM(K13:O13) -> 26.050116 | Q13: PCB价格有效期一周
B14: DN105(8L+通孔+OSP) | E14: 6.78 | F14: A.F.M.2501241 | J14: - | K14: 现询 | L14: - | M14: =62.5/E14/1.13 -> 8.157778 | N14: =15.4*1.05 -> 16.17 | O14: =22/E14 -> 3.2448378 | P14: =SUM(K14:O14) -> 27.572616 | Q14: PCB价格有效期一周
B15: DN87(8L++通孔+OSP) | C15: 258.0*128.0*1.0mm | D15: 46241 | E15: 6.78 | F15: A.F.M.2503104 | J15: - | K15: 现询 | L15: - | M15: =59.12/E15/1.13 -> 7.7166053 | N15: 14.2 | O15: 2.94 | P15: =SUM(K15:O15) -> 24.856605 | Q15: PCB有效期8-15 | R15: 12.866631 | S15: 条子 | T15: 电量计 ：CW2217; ROM:128Mb
B16: WS17(6L+通孔+OSP) | C16: 183.4*285.8*1.6 | E16: 6.75 | F16: A.F.M.2601815 | G16: SKU1 | J16: - | K16: 现询 | L16: - | M16: =340.5/E16/1.13 -> 44.641101 | N16: 55.6 | O16: =34/E16 -> 5.037037 | P16: =SUM(K16:O16) -> 105.27814 | Q16: PCB按快板厂价格,smt为批量预估价
B17: WS17(6L+通孔+OSP) | C17: 183.4*285.8*1.6 | E17: 6.75 | F17: A.F.M.2601816 | G17: SKU2 | J17: - | K17: 现询 | L17: - | M17: =340.5/E17/1.13 -> 44.641101 | N17: 54.9 | O17: =34/E17 -> 5.037037 | P17: =SUM(K17:O17) -> 104.57814 | Q17: PCB按快板厂价格,smt为批量预估价
B18: WS17(6L+通孔+OSP) | C18: 183.4*285.8*1.6 | E18: 6.75 | F18: A.F.M.2602249 | G18: SKU3 | J18: - | K18: 现询 | L18: - | M18: =340.5/E18/1.13 -> 44.641101 | N18: 54.8 | O18: =34/E18 -> 5.037037 | P18: =SUM(K18:O18) -> 104.47814 | Q18: PCB按快板厂价格,smt为批量预估价
B19: WS17(6L+通孔+OSP) | C19: 183.4*285.8*1.6 | E19: 6.72 | F19: A.F.M.2602505 | J19: - | K19: 现询 | L19: - | M19: =73.78/E19/1.13 -> 9.7160767 | N19: 57.7 | O19: =34/E19 -> 5.0595238 | P19: =SUM(K19:O19) -> 72.475601 | Q19: 65套PCB价格
B20: PS21(10L+通孔+OSP） | C20: 216.4*167.2*1.6mm | D20: 46275 | E20: 6.72 | F20: A.F.M.2602442 | J20: - | K20: 现询 | L20: - | M20: =352.5/E20/1.13 -> 46.42067 | N20: 77.1 | O20: =40/E20 -> 5.952381 | P20: =SUM(K20:O20) -> 129.47305 | Q20: LPDDR5X_8GB 315球*4 | R20: 不含屏蔽罩价格
B21: PS21(10L+通孔+OSP） | C21: 216.4*167.2*1.6mm | D21: 46275 | E21: 6.72 | F21: A.F.M.2602443 | J21: - | K21: 现询 | L21: - | M21: =352.5/E21/1.13 -> 46.42067 | N21: 77.7 | O21: =40/E21 -> 5.952381 | P21: =SUM(K21:O21) -> 130.07305 | Q21: LPDDR5X_8GB 315球*4 | R21: 不含屏蔽罩价格
B22: PS21(10L+通孔+OSP） | C22: 216.4*167.2*1.6mm | D22: 46275 | E22: 6.72 | F22: A.F.M.2602931 | J22: - | K22: 现询 | L22: - | M22: =352.5/E22/1.13 -> 46.42067 | N22: 77.7 | O22: =40/E22 -> 5.952381 | P22: =SUM(K22:O22) -> 130.07305 | Q22: LPDDR5X_16GB 315球*4 | R22: 不含屏蔽罩价格
B23: DN38 | E23: 6.78 | F23: A.F.M.2501241 | N23: =16.02*1.1 -> 17.622 | O23: =22/E23 -> 3.2448378
A24: 3 | B24: LP13（8L+HDI+沉金）预估LP13C | D24: 20251128 | E24: 7.01 | F24: A.F.M.2502474 | G24: SKU1 | H24: 双Type c(两个Type c接口)（LT7911D/CS32G053HRCW6NR） | I24: Ultra-5-226V(16GB) | J24: AX211.D2WG | K24: 选配 | L24: 7.5 | M24: =68.912/E220/1.13 -> 8.5054492 | N24: =29.9075200457023+2.5 -> 32.40752 | O24: 4 | P24: =SUM(L24:O24) -> 52.412969 | Q24: 条子 | R24: 此项目为预估报价，PCB直接参考LP13,Others部分建议参考A.F.M.2502474（LP13-SKU1、WIFI 6 WIFI AX211）+加一颗G2708C 芯片
A25: 1 | B25: LP13C（8L+HDI+OSP） | D25: 46126 | E25: 6.837 | F25: A.F.M.2600129 | L25: 7.5 | M25: =68.91/E25/1.3 -> 7.7530631 | N25: 30.1 | O25: 4 | P25: =SUBTOTAL(109,L25:O25) -> 49.353063
B26: PN50(8L+通孔+OSP) | D26: 20251229 | E26: 7.01 | F26: A.F.M.2600118 | H26: 单Type c(两个Type c接口)IT5272FN | I26: H-25W | J26: 选配 | K26: 选配 | L26: 选配 | N26: 28.2 | O26: 0.3 | P26: =SUM(M26:O26) -> 28.5 | Q26: 报价不含EPTAD-A5R，CKD
A27: 4 | B27: PN50(8L+通孔+OSP) | D27: 20251229 | E27: 7.01 | F27: / | H27: 单Type c(两个Type c接口)IT5272FN | I27: H-25W | J27: 选配 | K27: 选配 | L27: 选配 | M27: =60.16/E27/1.13 -> 7.594713 | N27: 29.581934 | O27: 4 | P27: =SUM(M27:O27) -> 41.176647 | Q27: 条子 | R27: 全功能(IT5272FN)；含加密IC TPM,含UDP;pcb按样品单价核算
A28: 6 | B28: WN25(6L+通孔+OSP) | C28: 187.0*99.2*1.0mm | D28: 46087 | E28: 6.8226 | F28: A.F.M.2600389 | G28: SKU3 | H28: 单Type c(两个Type c接口)IT5272FN | I28: 25W | J28: BE211.D2WG.NVQ | K28: 现询 | L28: 11.5 | M28: =17.24/E28/1.13 -> 2.2361911 | N28: =14.4+0.57 -> 14.97 | O28: =20.5/E28 -> 3.0047196 | P28: =SUM(L28:O28) -> 31.710911 | Q28: 0+512 UFS | R28: HDMI2.0,ROM:256Mb,含496球DDR转接小板,
A29: 1 | C29: 187.0*99.2*1.0mm | D29: 46136 | E29: 6.8225 | F29: A.F.M.2600388 | G29: SKU2 | H29: 单Type c(两个Type c接口)IT5272FN | I29: 25W | J29: WD_RTL8821CE_V20(MS) | K29: 现询 | L29: =12.9/E29/1.13 -> 1.6732765 | M29: =17.24/E29/1.13 -> 2.2362238 | N29: =15.3+0.57 -> 15.87 | O29: =20.5/E29 -> 3.0047636 | P29: =SUM(L29:O29) -> 22.784264 | Q29: 496球（小板）+512 UFS | R29: HDMI2.0,TPM,ROM 256Mb,含496球DDR转接小板
A30: 1 | C30: 187.0*99.2*1.0mm | D30: 46163 | E30: 6.8 | F30: A.F.M.2601423 | J30: - | K30: 现询 | L30: - | M30: =32.32/E30/1.13 -> 4.2061426 | N30: 15.2 | O30: =20.5/E30 -> 3.0147059 | P30: =SUM(L30:O30) -> 22.420849
A31: 1 | C31: 187.0*99.2*1.0mm | D31: 46175 | E31: 6.8 | F31: A.F.M.2601434 | M31: =26.51/E31/1.13 -> 3.450026 | N31: 16.4 | O31: =20.5/E31 -> 3.0147059 | P31: =SUM(L31:O31) -> 22.864732 | R31: PCB无卤
A32: 1 | C32: 187.0*99.2*1.0mm | D32: 46134 | E32: 6.8225 | F32: A.F.M.2600780 | G32: SKU5 | H32: 单Type c(两个Type c接口)IT5272FN | I32: 25W | J32: CDW-61851BE-00 | K32: 现询 | L32: =17.46/E32/1.13 -> 2.2647603 | M32: =17.24/E32/1.13 -> 2.2362238 | N32: 13.5 | O32: =20.1/E32 -> 2.9461341 | P32: =SUM(L32:O32) -> 20.947118 | Q32: 条子
A33: 1 | C33: 187.0*99.2*1.0mm | D33: 46135 | E33: 6.8225 | F33: A.F.M.2600839 | G33: SKU10 | H33: 单Type c(两个Type c接口)IT5272FN | J33: CDW-61852BE-00 | K33: 现询 | L33: =25.72/E33/1.13 -> 3.3361762 | M33: =18.89/E33/1.13 -> 2.4502476 | N33: =14.4+0.57 -> 14.97 | O33: =20.5/E33 -> 3.0047636 | P33: =SUM(L33:O33) -> 23.761187 | Q33: 条子 | R33: HDMI2.0.无卤PCB,含496转接小板
A34: 1 | C34: 187.0*99.2*1.0mm | D34: 46135 | E34: 6.8225 | F34: A.F.M.2600853 | G34: SKU11 | H34: 单Type c(两个Type c接口)IT5272FN | J34: - | K34: 现询 | L34: - | M34: =23.2/E34/1.13*1.2 -> 3.6111643 | N34: 16.8 | O34: =20.1/E34+0.1 -> 3.0461341 | P34: =SUM(L34:O34) -> 23.457298 | Q34: 条子 | R34: HDMI2.0,含496转接小板，HFPCB
A35: 7 | C35: 187.0*99.2*1.0mm | D35: 46101 | E35: 6.8225 | F35: A.F.M.2600390 | G35: SKU4 | H35: 单Type c(两个Type c接口)IT5272FN | I35: 25W | J35: AX211.D2WG | K35: 现询 | L35: 7.5 | M35: =17.24/E35/1.13 -> 2.2362238 | N35: 14.1 | O35: =20.1/E35 -> 2.9461341 | P35: =SUM(L35:O35) -> 26.782358 | Q35: LPDDR5-315球8G*2+256 UFS | R35: HDMI2.0,ROM:256Mb
A36: 1 | C36: 187.0*99.2*1.0mm | D36: 20251224 | E36: 6.8225 | F36: A.F.M.2503155 | G36: SKU1 | H36: 单Type C IC及两个Type C 接口（IT5272FN） | I36: 15w | J36: AX211.D2WG | K36: 现询 | L36: 7.5 | M36: =17.24/E36/1.13 -> 2.2362238 | N36: 14.7 | O36: =20.1/E36 -> 2.9461341 | P36: =SUM(M36:O36) -> 19.882358 | Q36: LPDDR5-315球8G*2+0 | R36: HDMI2.0/TPM/ROM 256Mb
A37: 1 | B37: RPLK3（6L+通孔+OSP) | C37: 184x170x1.6mm | D37: 46128 | E37: 6.7739 | F37: A.F.M.2600743 | J37: - | K37: 现询 | L37: - | M37: =41.68/E37/1.13 -> 5.445158 | N37: 18 | O37: =32/E37 -> 4.7240142 | P37: =SUBTOTAL(109,M37:O37) -> 28.169172
A38: 1 | B38: RPLK3（6L+通孔+OSP) | C38: 184x170x1.6mm | D38: 46128 | E38: 6.7739 | F38: A.F.M.2600589 | J38: - | K38: 现询 | L38: - | M38: =32.35/E38/1.13 -> 4.2262683 | N38: 15.8 | O38: =32/E38 -> 4.7240142 | P38: =SUBTOTAL(109,M38:O38) -> 24.750282
A39: 1 | B39: RPLK3（6L+通孔+OSP) | C39: 184x170x1.6mm | D39: 46128 | E39: 6.7739 | F39: A.F.M.2600590 | J39: - | K39: 现询 | L39: - | M39: =32.35/E39/1.13 -> 4.2262683 | N39: 15.8 | O39: =32/E39 -> 4.7240142 | P39: =SUBTOTAL(109,M39:O39) -> 24.750282
A40: 1 | B40: RPLK3（6L+通孔+OSP) | C40: 184x170x1.6mm | D40: 46153 | E40: 6.7986 | F40: A.F.M.2601222 | M40: =32.35/E40/1.13 -> 4.2109138 | N40: 15.6
...

Sheet E BOM大核 (3)
B1: 汇率：6.75 | S1: pcb为普通材质OSP工艺，如用特殊材质请单独核;CPU;DDR;SSD;EMMC;WIFI请按需求选配 | U1: - | V1: 类型 | W1: 型号 | X1: 美金单项单价 | Z1: - | AA1: 类型 | AB1: 型号 | AC1: 美金单项单价
U2: - | V2: TYPC IC | W2: ANX7447QN | X2: 0.64 | Z2: - | AA2: 加密IC TPM | AB2: 9672 | AC2: 1.05
U3: - | W3: CYPD6228 | X3: 1.7769148 | Z3: - | AA3: 电量计 | AB3: CW2217 | AC3: 0.23
U4: - | W4: CYPD6227 | X4: 1.8079 | Z4: - | AA4: 雷电IC | AB4: 8040 | AC4: 2.948
U5: - | W5: ASL2330AN | X5: 0.52 | Z5: - | AB5: 9040 | AC5: 3.054
W6: IT8856FN/CX | X6: 0.93
B7: WN35B 成本差异说明
A8: 厂区 | B8: 机型 | C8: PCB尺寸 | D8: 日期 | E8: 汇率 | F8: 料号 | G8: SKU | H8: Type c | I8: 功率 | J8: WIFI | K8: DDR 存储 | L8: WIFI | M8: PCB | N8: Others | O8: SMT | P8: 小板 | Q8: TTL | R8: 备注 | S8: 已含型号备注
A9: 1 | B9: ROBOT临时核价20260104 | D9: 20260104 | E9: 7.01 | F9: A.F.M.2401621-MP | J9: NA | K9: 选配 | L9: NA | M9: =[2]深圳英众PCB单价清单!$P$1014/E9/1.13 -> 3.7241362 | N9: 41.248623 | O9: 3.5 | Q9: =SUM(K9:O9) -> 48.472759 | R9: 条子 | S9: pcb按MTN25机型参考报价，SMT预估，后续正式bom再按实际核价为准,不含keypark报价
A10: 2 | B10: ROBOT临时核价20260105小板 | F10: A.F.M.2401623-MP | J10: NA | K10: NA | L10: NA | M10: 0.6 | N10: 0.48775694 | O10: 0.5 | Q10: =SUM(K10:O10) -> 1.5877569 | R10: 条子 | S10: pcb按xn25预估，smt预估
B11: DNN253 | E11: 6.78 | F11: A.F.M.2602447 | J11: - | K11: 现询 | L11: - | M11: =27.8/E11/1.13 -> 3.6285796 | N11: 14.1 | O11: =22/E11 -> 3.2448378 | Q11: =SUM(K11:O11) -> 20.973417 | R11: 条子 | S11: PCB持续上涨，实单前重新确认
B12: WN38(8L+通孔+OSP) | E12: 6.78 | F12: A.F.M.2400978 | H12: =H10-H11 -> 0 | J12: - | K12: 现询 | L12: - | M12: =58.17/E12/1.13*1.05 -> 7.9722375 | N12: =16.4*1.05 -> 17.22 | O12: =23/E12 -> 3.3923304 | Q12: =SUM(K12:O12) -> 28.584568 | R12: PCB价保一周
B13: WN38(8L+通孔+OSP) | E13: 6.78 | F13: A.F.M.2400991 | J13: - | K13: 现询 | L13: - | M13: =58.17/E13/1.13*1.05 -> 7.9722375 | N13: =16.4*1.05 -> 17.22 | O13: =23/E13 -> 3.3923304 | Q13: =SUM(K13:O13) -> 28.584568 | R13: PCB价保一周
B14: DN105(8L+通孔+OSP) | E14: 6.78 | F14: A.F.M.2501240 | J14: - | K14: 现询 | L14: - | M14: =62.5/E14/1.13 -> 8.157778 | N14: =13.95*1.05 -> 14.6475 | O14: =22/E14 -> 3.2448378 | Q14: =SUM(K14:O14) -> 26.050116 | R14: PCB价格有效期一周
B15: DN105(8L+通孔+OSP) | E15: 6.78 | F15: A.F.M.2501241 | J15: - | K15: 现询 | L15: - | M15: =62.5/E15/1.13 -> 8.157778 | N15: =15.4*1.05 -> 16.17 | O15: =22/E15 -> 3.2448378 | Q15: =SUM(K15:O15) -> 27.572616 | R15: PCB价格有效期一周
B16: DN87(8L++通孔+OSP) | C16: 258.0*128.0*1.0mm | D16: 46241 | E16: 6.78 | F16: A.F.M.2503104 | J16: - | K16: 现询 | L16: - | M16: =59.12/E16/1.13 -> 7.7166053 | N16: 14.2 | O16: 2.94 | Q16: =SUM(K16:O16) -> 24.856605 | R16: PCB有效期8-15 | S16: 12.866631 | T16: 条子 | U16: 电量计 ：CW2217; ROM:128Mb
B17: WS17(6L+通孔+OSP) | C17: 183.4*285.8*1.6 | E17: 6.75 | F17: A.F.M.2601815 | G17: SKU1 | J17: - | K17: 现询 | L17: - | M17: =340.5/E17/1.13 -> 44.641101 | N17: 55.6 | O17: =34/E17 -> 5.037037 | Q17: =SUM(K17:O17) -> 105.27814 | R17: PCB按快板厂价格,smt为批量预估价
B18: WS17(6L+通孔+OSP) | C18: 183.4*285.8*1.6 | E18: 6.75 | F18: A.F.M.2601816 | G18: SKU2 | J18: - | K18: 现询 | L18: - | M18: =340.5/E18/1.13 -> 44.641101 | N18: 54.9 | O18: =34/E18 -> 5.037037 | Q18: =SUM(K18:O18) -> 104.57814 | R18: PCB按快板厂价格,smt为批量预估价
B19: WS17(6L+通孔+OSP) | C19: 183.4*285.8*1.6 | E19: 6.75 | F19: A.F.M.2602249 | G19: SKU3 | J19: - | K19: 现询 | L19: - | M19: =340.5/E19/1.13 -> 44.641101 | N19: 54.8 | O19: =34/E19 -> 5.037037 | Q19: =SUM(K19:O19) -> 104.47814 | R19: PCB按快板厂价格,smt为批量预估价
B20: WS17(6L+通孔+OSP) | C20: 183.4*285.8*1.6 | E20: 6.72 | F20: A.F.M.2602505 | J20: - | K20: 现询 | L20: - | M20: =73.78/E20/1.13 -> 9.7160767 | N20: 57.7 | O20: =34/E20 -> 5.0595238 | Q20: =SUM(K20:O20) -> 72.475601 | R20: 65套PCB价格
B21: PS21(10L+通孔+OSP） | C21: 216.4*167.2*1.6mm | D21: 46275 | E21: 6.72 | F21: A.F.M.2602442 | J21: - | K21: 现询 | L21: - | M21: =352.5/E21/1.13 -> 46.42067 | N21: 77.1 | O21: =40/E21 -> 5.952381 | Q21: =SUM(K21:O21) -> 129.47305 | R21: LPDDR5X_8GB 315球*4 | S21: 不含屏蔽罩价格
B22: PS21(10L+通孔+OSP） | C22: 216.4*167.2*1.6mm | D22: 46275 | E22: 6.72 | F22: A.F.M.2602443 | J22: - | K22: 现询 | L22: - | M22: =352.5/E22/1.13 -> 46.42067 | N22: 77.7 | O22: =40/E22 -> 5.952381 | Q22: =SUM(K22:O22) -> 130.07305 | R22: LPDDR5X_8GB 315球*4 | S22: 不含屏蔽罩价格
B23: PS21(10L+通孔+OSP） | C23: 216.4*167.2*1.6mm | D23: 46275 | E23: 6.72 | F23: A.F.M.2602931 | J23: - | K23: 现询 | L23: - | M23: =352.5/E23/1.13 -> 46.42067 | N23: 77.7 | O23: =40/E23 -> 5.952381 | Q23: =SUM(K23:O23) -> 130.07305 | R23: LPDDR5X_16GB 315球*4 | S23: 不含屏蔽罩价格
B24: DN38 | E24: 6.78 | F24: A.F.M.2501241 | N24: =16.02*1.1 -> 17.622 | O24: =22/E24 -> 3.2448378
A25: 3 | B25: LP13（8L+HDI+沉金）预估LP13C | D25: 20251128 | E25: 7.01 | F25: A.F.M.2502474 | G25: SKU1 | H25: 双Type c(两个Type c接口)（LT7911D/CS32G053HRCW6NR） | I25: Ultra-5-226V(16GB) | J25: AX211.D2WG | K25: 选配 | L25: 7.5 | M25: =68.912/E220/1.13 -> 8.5054492 | N25: =29.9075200457023+2.5 -> 32.40752 | O25: 4 | Q25: =SUM(L25:O25) -> 52.412969 | R25: 条子 | S25: 此项目为预估报价，PCB直接参考LP13,Others部分建议参考A.F.M.2502474（LP13-SKU1、WIFI 6 WIFI AX211）+加一颗G2708C 芯片
A26: 1 | B26: LP13C（8L+HDI+OSP） | D26: 46126 | E26: 6.837 | F26: A.F.M.2600129 | L26: 7.5 | M26: =68.91/E26/1.3 -> 7.7530631 | N26: 30.1 | O26: 4 | Q26: =SUBTOTAL(109,L26:O26) -> 0
B27: PN50(8L+通孔+OSP) | D27: 20251229 | E27: 7.01 | F27: A.F.M.2600118 | H27: 单Type c(两个Type c接口)IT5272FN | I27: H-25W | J27: 选配 | K27: 选配 | L27: 选配 | N27: 28.2 | O27: 0.3 | Q27: =SUM(M27:O27) -> 28.5 | R27: 报价不含EPTAD-A5R，CKD
A28: 4 | B28: PN50(8L+通孔+OSP) | D28: 20251229 | E28: 7.01 | F28: / | H28: 单Type c(两个Type c接口)IT5272FN | I28: H-25W | J28: 选配 | K28: 选配 | L28: 选配 | M28: =60.16/E28/1.13 -> 7.594713 | N28: 29.581934 | O28: 4 | Q28: =SUM(M28:O28) -> 41.176647 | R28: 条子 | S28: 全功能(IT5272FN)；含加密IC TPM,含UDP;pcb按样品单价核算
A29: 6 | B29: WN25(6L+通孔+OSP) | C29: 187.0*99.2*1.0mm | D29: 46087 | E29: 6.8226 | F29: A.F.M.2600389 | G29: SKU3 | H29: 单Type c(两个Type c接口)IT5272FN | I29: 25W | J29: BE211.D2WG.NVQ | K29: 现询 | L29: 11.5 | M29: =17.24/E29/1.13 -> 2.2361911 | N29: =14.4+0.57 -> 14.97 | O29: =20.5/E29 -> 3.0047196 | Q29: =SUM(L29:O29) -> 31.710911 | R29: 0+512 UFS | S29: HDMI2.0,ROM:256Mb,含496球DDR转接小板,
A30: 1 | C30: 187.0*99.2*1.0mm | D30: 46136 | E30: 6.8225 | F30: A.F.M.2600388 | G30: SKU2 | H30: 单Type c(两个Type c接口)IT5272FN | I30: 25W | J30: WD_RTL8821CE_V20(MS) | K30: 现询 | L30: =12.9/E30/1.13 -> 1.6732765 | M30: =17.24/E30/1.13 -> 2.2362238 | N30: =15.3+0.57 -> 15.87 | O30: =20.5/E30 -> 3.0047636 | Q30: =SUM(L30:O30) -> 22.784264 | R30: 496球（小板）+512 UFS | S30: HDMI2.0,TPM,ROM 256Mb,含496球DDR转接小板
A31: 1 | C31: 187.0*99.2*1.0mm | D31: 46163 | E31: 6.8 | F31: A.F.M.2601423 | J31: - | K31: 现询 | L31: - | M31: =32.32/E31/1.13 -> 4.2061426 | N31: 15.2 | O31: =20.5/E31 -> 3.0147059 | Q31: =SUM(L31:O31) -> 22.420849
A32: 1 | C32: 187.0*99.2*1.0mm | D32: 46175 | E32: 6.8 | F32: A.F.M.2601434 | M32: =26.51/E32/1.13 -> 3.450026 | N32: 16.4 | O32: =20.5/E32 -> 3.0147059 | Q32: =SUM(L32:O32) -> 22.864732 | S32: PCB无卤
A33: 1 | C33: 187.0*99.2*1.0mm | D33: 46134 | E33: 6.8225 | F33: A.F.M.2600780 | G33: SKU5 | H33: 单Type c(两个Type c接口)IT5272FN | I33: 25W | J33: CDW-61851BE-00 | K33: 现询 | L33: =17.46/E33/1.13 -> 2.2647603 | M33: =17.24/E33/1.13 -> 2.2362238 | N33: 13.5 | O33: =20.1/E33 -> 2.9461341 | Q33: =SUM(L33:O33) -> 20.947118 | R33: 条子
A34: 1 | C34: 187.0*99.2*1.0mm | D34: 46135 | E34: 6.8225 | F34: A.F.M.2600839 | G34: SKU10 | H34: 单Type c(两个Type c接口)IT5272FN | J34: CDW-61852BE-00 | K34: 现询 | L34: =25.72/E34/1.13 -> 3.3361762 | M34: =18.89/E34/1.13 -> 2.4502476 | N34: =14.4+0.57 -> 14.97 | O34: =20.5/E34 -> 3.0047636 | Q34: =SUM(L34:O34) -> 23.761187 | R34: 条子 | S34: HDMI2.0.无卤PCB,含496转接小板
A35: 1 | C35: 187.0*99.2*1.0mm | D35: 46135 | E35: 6.8225 | F35: A.F.M.2600853 | G35: SKU11 | H35: 单Type c(两个Type c接口)IT5272FN | J35: - | K35: 现询 | L35: - | M35: =23.2/E35/1.13*1.2 -> 3.6111643 | N35: 16.8 | O35: =20.1/E35+0.1 -> 3.0461341 | Q35: =SUM(L35:O35) -> 23.457298 | R35: 条子 | S35: HDMI2.0,含496转接小板，HFPCB
A36: 7 | C36: 187.0*99.2*1.0mm | D36: 46101 | E36: 6.8225 | F36: A.F.M.2600390 | G36: SKU4 | H36: 单Type c(两个Type c接口)IT5272FN | I36: 25W | J36: AX211.D2WG | K36: 现询 | L36: 7.5 | M36: =17.24/E36/1.13 -> 2.2362238 | N36: 14.1 | O36: =20.1/E36 -> 2.9461341 | Q36: =SUM(L36:O36) -> 26.782358 | R36: LPDDR5-315球8G*2+256 UFS | S36: HDMI2.0,ROM:256Mb
A37: 1 | C37: 187.0*99.2*1.0mm | D37: 20251224 | E37: 6.8225 | F37: A.F.M.2503155 | G37: SKU1 | H37: 单Type C IC及两个Type C 接口（IT5272FN） | I37: 15w | J37: AX211.D2WG | K37: 现询 | L37: 7.5 | M37: =17.24/E37/1.13 -> 2.2362238 | N37: 14.7 | O37: =20.1/E37 -> 2.9461341 | Q37: =SUM(M37:O37) -> 19.882358 | R37: LPDDR5-315球8G*2+0 | S37: HDMI2.0/TPM/ROM 256Mb
A38: 1 | B38: RPLK3（6L+通孔+OSP) | C38: 184x170x1.6mm | D38: 46128 | E38: 6.7739 | F38: A.F.M.2600743 | J38: - | K38: 现询 | L38: - | M38: =41.68/E38/1.13 -> 5.445158 | N38: 18 | O38: =32/E38 -> 4.7240142 | Q38: =SUBTOTAL(109,M38:O38) -> 0
A39: 1 | B39: RPLK3（6L+通孔+OSP) | C39: 184x170x1.6mm | D39: 46128 | E39: 6.7739 | F39: A.F.M.2600589 | J39: - | K39: 现询 | L39: - | M39: =32.35/E39/1.13 -> 4.2262683 | N39: 15.8 | O39: =32/E39 -> 4.7240142 | Q39: =SUBTOTAL(109,M39:O39) -> 0
A40: 1 | B40: RPLK3（6L+通孔+OSP) | C40: 184x170x1.6mm | D40: 46128 | E40: 6.7739 | F40: A.F.M.2600590 | J40: - | K40: 现询 | L40: - | M40: =32.35/E40/1.13 -> 4.2262683 | N40: 15.8 | O40: =32/E40 -> 4.7240142 | Q40: =SUBTOTAL(109,M40:O40) -> 0
...

Sheet E BOM小核
V1: pcb为普通材质OSP工艺，如用特殊材质请单独核;CPU;DDR;SSD;EMMC;WIFI请按需求选配 | W1: - | X1: 类型 | Y1: 型号 | Z1: 美金单项单价 | AB1: - | AC1: 类型 | AD1: 型号 | AE1: 美金单项单价
W2: - | X2: TYPEC IC | Y2: ANX7447QN | Z2: 0.64 | AB2: - | AC2: 加密IC TPM | AD2: 9672 | AE2: 1.05
B3: 9月份汇率：6.71 | F3: 6月份汇率：6.8 | H3: 币种:USD | W3: - | Y3: CYPD6228 | Z3: 1.7769148 | AB3: - | AC3: 电量计 | AD3: CW2217 | AE3: 0.23
W4: - | Y4: CYPD6227 | Z4: 1.75 | AB4: - | AC4: 雷电IC | AD4: 8040 | AE4: 2.948
W5: - | Y5: ASL2330AN | Z5: 0.52 | AB5: - | AD5: 9040 | AE5: 3.054
Y6: IT8856FN/CX | Z6: 0.93
B7: 机型 | C7: PCB尺寸 | D7: 日期 | E7: 更新汇率 | F7: 料号 | G7: 规格 | H7: Type c | I7: 功率 | J7: 配置 | K7: WIFI | L7: CPU 存储 | M7: WIFI | N7: PCB | O7: PCB | P7: PCB | Q7: Others | R7: SMT | S7: TTL | U7: DDR/SSD | V7: 备注
A8: 2 | B8: DNN21S（6L+通孔+OSP） | C8: 214.5*119.9*1.0mm | D8: 20250901 | E8: 6.75 | F8: A.F.M.2302171-MP | G8: SKU22 | H8: 单Tpye c IC及单Type c接口（ANX7447QN） | I8: N-15W | J8: 0+128G | K8: 选配 | L8: 现询 | M8: 选配 | N8: =25.7/E8/1.13 -> 3.3693871 | O8: 5.57 | P8: 6.127 | Q8: 15.2 | R8: =21.1/E8/1.13 -> 2.7663061 | S8: =SUBTOTAL(109,P8:R8) -> 24.093306 | T8: 13.05 | U8: 条子 | V8: TPM:SLB 9672; 电量计： CW2015CHBD； ROM:128Mb;
A9: 2 | B9: DNN25（6L+通孔+OSP） | C9: 188.1*99.2*1.0mm | D9: 20250901 | E9: 6.75 | F9: A.F.M.250000X | G9: 全配 | H9: 双Type C IC及双Type c接口(ANX7447QN) | I9: N-15W | J9: 0+0 | K9: 选配 | L9: 现询 | M9: 选配 | N9: =26.63/E9/1.13 -> 3.4913143 | O9: 4.1587715 | P9: 4.5746486 | Q9: 17.92 | R9: =20.4/E9/1.13 -> 2.6745329 | S9: =SUBTOTAL(109,P9:R9) -> 25.169182 | T9: 14.53 | U9: LPDDR5-315球8G*2(江波龙) | V9: HDMI2.0 IT66318FN; TPM:SLB 9672;电量计：CW2217; ROM:128Mb;
A10: 2 | B10: JN11S(8L+通孔+OSP) | C10: 184.2*110.8*1.0mm | D10: 20250902 | E10: 6.75 | F10: A.F.M.2500669 | G10: SKU28 | H10: 单Type IC及Type C 单接口(ANX7447QN) | I10: N-15W | J10: 0+0 | K10: AX101.D2WG | L10: 现询 | M10: 选配 | N10: =22.47/E10/1.13 -> 2.9459194 | O10: =42.48/6.78/1.13 -> 5.5446785 | P10: 6.0991464 | Q10: 15.6 | R10: =23.45/E10/1.13 -> 3.0744018 | S10: =SUBTOTAL(109,P10:R10) -> 24.773548 | T10: 13 | U10: 条子 | V10: TPM:SLB 9672; 电量计：CW2015CHBD； ROM:128Mb ;
A11: 2 | B11: DNNXU(6L+通孔+OSP) | C11: 207.0*178.7*1.0mm | D11: 20250904 | E11: 6.75 | F11: A.F.M.2401323-MP | G11: SKU13 | H11: 单Tpye c IC及单Type c接口（ANX7447QN） | I11: N-15W | J11: 0+0 | K11: 选配 | L11: 现询 | M11: 选配 | N11: =17/E11/1.13 -> 2.2287775 | O11: 2.6548673 | P11: 2.920354 | Q11: 14.8 | R11: =19.77/E11/1.13 -> 2.5919371 | S11: =SUBTOTAL(109,P11:R11) -> 20.312291 | T11: 12.3 | U11: 条子 | V11: 电量计：CW2015CHBD； ROM:128Mb ;
A12: 2 | B12: DNN11S(8L+通孔+OSP) | C12: 184.2*110.8*1.0 | D12: 20250909 | E12: 6.75 | F12: A.F.M.2500505-MP | G12: SKU16 | H12: 单Tpye c IC及双Type c接口（ANX7447QN） | I12: N-6W | J12: 0+0 | K12: AX201.D2WG.NVW | L12: 现询 | M12: 选配 | N12: =27.55/E12/1.13 -> 3.6119305 | O12: 4.3024466 | P12: =51.02/E12/1.13*1.05 -> 7.0234022 | Q12: 17.1 | R12: =20.1/E12/1.13 -> 2.6352016 | S12: =SUBTOTAL(109,P12:R12) -> 26.758604 | T12: 13.4 | U12: 条子 | V12: TPM:SLB 9672; 电量计：CW2015CHBD； ROM:128Mb ;
A13: 2 | B13: DNP13C(6L+通孔+OSP) | C13: 211.7*102.0*1.0MM | D13: 20250902 | E13: 6.75 | F13: A.F.M.2502098 | G13: SKU17 | H13: 双Type c IC(双Type C 接口)(ANX7447QN) | I13: N-15W | J13: 0+0 | K13: 选配 | L13: 现询 | M13: 选配 | N13: =33.47/E13/1.13*1.2 -> 5.2656834 | O13: 6.2723581 | P13: =38.12/6.72/1.13*1.05 -> 5.2710177 | Q13: 18.4 | R13: =21.72/E13/1.13 -> 2.847591 | S13: =SUBTOTAL(109,P13:R13) -> 26.518609 | T13: 15.5 | U13: LPDDR5X-315球4G*2 | V13: ROM:128Mb
B14: DNN21(8L+HDI3+OSP) | C14: 214.5*119.9*1.0mm | D14: 20250909 | E14: 6.75 | F14: A.F.M.2401219-MP | G14: SKU9 | H14: 单Type c IC及单Type c 接口（ANX7447QN） | I14: N-15W | J14: 0+0 | K14: 选配 | L14: 现询 | M14: 选配 | N14: =74.66/E14/1.13 -> 9.7882661 | O14: 11.659552 | P14: 12.825508 | Q14: 16 | R14: =24.43/E14/1.13 -> 3.2028843 | S14: =SUBTOTAL(109,P14:R14) -> 32.028392 | T14: 11.9 | U14: LPDDR5-496球16G | V14: 电量计：CW2015CHBD； ROM:128Mb ;
A15: 2 | B15: DNN21F(6L+通孔+OSP) | C15: 214.9*119.9*1.0mm | D15: 20250910 | E15: 6.75 | F15: A.F.M.2402477-PVT | G15: SKU6 | H15: Type c(l双Type C 接口)(ANX7447QN) | I15: N-15w | J15: 0+128G | K15: 选配 | L15: 现询 | M15: 选配 | N15: =23.1/E15/1.13 -> 3.0285152 | O15: 3.6074961 | P15: 3.9682457 | Q15: 16.6 | R15: 2.6608507 | S15: =SUBTOTAL(109,P15:R15) -> 23.229096 | T15: 13.9 | U15: 群联/条子 | V15: HDMI2.0:IT66318FN; TPM:SLB 9672; USB3-10G:GL9901VAE; 电量计：CW2217; ROM:128Mb
A16: 2 | B16: DNN81S(6L+通孔+OSP) | C16: 190.0*114.0*1.0mm | D16: 20250912 | E16: 6.75 | F16: A.F.M.2402361-OOC3 | G16: SKU6 | H16: Type Ic(单Type c 接口)ANX7447QN | I16: N-6W | J16: 0+0 | K16: 选配 | L16: 现询 | M16: 选配 | N16: =20.2954/E16/1.13 -> 2.6608194 | O16: =28.6/6.78/1.13 -> 3.7329992 | P16: 4.1062991 | Q16: 14.8 | R16: =18.6/E16/1.13 -> 2.4385447 | S16: =SUBTOTAL(109,P16:R16) -> 21.344844 | T16: 11.6 | U16: 条子 | V16: 电量计：CW2015CHBD； ROM:128Mb ;
A17: 2 | B17: DNNTU146(4L+通孔+OSP) | C17: 207*131*1.0mm | D17: 20250806 | E17: 6.75 | F17: A.F.M.2501936-PVT | G17: SKU3 | H17: Type c(l双Type C 接口)(ANX7447QN) | I17: N-6W | J17: 0+0 | K17: 原RTL8821CE待更新 | L17: 现询 | M17: 选配 | N17: =21.57/E17/1.13 -> 2.8279253 | O17: 4.46 | P17: 4.906 | Q17: 13 | R17: =18.52/E17/1.13 -> 2.4280564 | S17: =SUBTOTAL(109,P17:R17) -> 20.334056 | T17: 10.43 | U17: 条子 | V17: 电量计：CW2217； ROM:128Mb ;
A18: 2 | B18: DNNTU146(4L+通孔+OSP) | C18: 207*131*1.0mm | D18: 20250806 | E18: 6.75 | F18: A.F.M.2501938 | G18: SKU5 | H18: Type c(l双Type C 接口)(ANX7447QN) | I18: N-15W | J18: 0+0 | K18: 8852BE | L18: 现询 | M18: 选配 | N18: =21.57/E18/1.13 -> 2.8279253 | O18: 4.46 | P18: 4.906 | Q18: 13.6 | R18: =18.52/E18/1.13 -> 2.4280564 | S18: =SUBTOTAL(109,P18:R18) -> 20.934056 | T18: 11.1 | U18: 条子 | V18: 电量计：CW2217； ROM:128Mb ;
A19: 2 | B19: JN106(6L+通孔+OSP) | C19: 189.9*114.0*1.0mm | D19: 20250626 | E19: 6.75 | F19: A.F.M.2501350-EVT | G19: SKU2 | H19: Type c(单Type C 接口)ANX7447QN | I19: N-6W | J19: 0+0 | K19: 选配 | L19: 现询 | M19: 选配 | N19: =21.65/E19/1.13 -> 2.8384136 | O19: 3.3810515 | P19: 3.7191567 | Q19: 14.4 | R19: =18.5/E19 -> 2.7407407 | S19: =SUBTOTAL(109,P19:R19) -> 20.859897 | T19: 12.3 | U19: 条子 | V19: 电量计：CW2015CHBD； ROM:128Mb ;
A20: 2 | B20: JN21S（8L+通孔+OSP） | C20: 214.5*119.9*1.0mm | D20: 20250916 | E20: 6.75 | F20: A.F.M.2302474 | G20: SKU1 | H20: Type c(双Type C 接口)(ANX7447QN) | I20: N-15W | J20: 0+0 | K20: 选配 | L20: 现询 | M20: 选配 | N20: =28.42/E20/1.13 -> 3.7259915 | O20: 4.4383134 | P20: 4.8821447 | Q20: 14.1 | R20: =22/E20/1.13 -> 2.8843002 | S20: =SUBTOTAL(109,P20:R20) -> 21.866445 | T20: 12.3 | U20: 条子 | V20: ROM:128Mb
A21: 2 | B21: JN21S（8L+通孔+OSP） | C21: 214.5*119.9*1.0mm | D21: 20250916 | E21: 6.75 | F21: A.F.M.2501017 | G21: SKU11 | H21: Type c(双Type C 接口)(ANX7447QN) | I21: N-6W | J21: 0+0 | K21: 选配 | L21: 现询 | M21: 选配 | N21: =28.42/E21/1.13 -> 3.7259915 | O21: 4.4383134 | P21: 4.8821447 | Q21: 13.9 | R21: =22/E21/1.13 -> 2.8843002 | S21: =SUBTOTAL(109,P21:R21) -> 21.666445 | T21: 11.1 | U21: 条子 | V21: ROM:128Mb
A22: 2 | B22: DNP28A(8L+HDI1+OSP) | C22: 155.0*89.0*1.2mm | D22: 20250915 | E22: 6.75 | F22: A.F.M.2302473-MP | G22: SKU4 | H22: 单Type c IC及单Type c 接口（ANX7447QN） | I22: N-15W | J22: 16G+256G | K22: AX201.D2WG | L22: 现询 | M22: 选配 | N22: =16.56/E22/1.13 -> 2.1710914 | O22: 2.586153 | P22: 2.8447683 | Q22: 16.7 | R22: =19.63/E22 -> 2.9081481 | S22: =SUBTOTAL(109,P22:R22) -> 22.452916 | T22: 14.8 | U22: LPDDR5-496球16G，EMMC群联 | V22: 电量计：CW2015CHBD； ROM:128Mb ;
A23: 2 | B23: DNN15B(8L+HDI1+OSP) | C23: 164.4*101.6*1.0mm | D23: 20250923 | E23: 6.75 | F23: A.F.M.2301127 | G23: SKU5 | H23: 单Type IC及Type C 单接口(ANX7447QN) | I23: N-15W | J23: 16G+0 | K23: 9560.D2WG | L23: 现询 | M23: 选配 | N23: =31.44/E23/1.13 -> 4.1219272 | O23: 4.9099427 | P23: =43.7/6.73/1.13*1.05 -> 6.0336099 | Q23: 13.9 | R23: =20.51/E23/1.13 -> 2.6889544 | S23: =SUBTOTAL(109,P23:R23) -> 22.622564 | T23: 11.9 | U23: LPDDR5-496球16G | V23: 全功能(ANX7447QN);
A24: 2 | B24: DNN20A(6L+通孔+OSP) | C24: 171.2*105.5*1.0 | D24: 20251009 | E24: 6.75 | F24: A.F.M.2500693 | G24: SKU9 | H24: 双Type C IC及双Type c接口(ANX7447QN) | I24: N-6W | J24: 16G+0 | K24: AX101.D2WG | L24: 现询 | M24: 选配 | N24: =42.7/E24/1.13 -> 5.5981645 | O24: 6.6684019 | P24: 7.3352421 | Q24: 17.8 | R24: =23.83/E24/1.13 -> 3.1242216 | S24: =SUBTOTAL(109,P24:R24) -> 28.259464 | T24: 14.83 | U24: LPDDR5X-496球16G | V24: 全功能(ANX7447QN);定制案
A25: 2 | B25: DNS13(8L+通孔+OSP) | C25: 150*101.1 | D25: 46056 | E25: 6.75 | F25: A.F.M.2501899-MP A.F.M.2502886 | G25: SKU5 | H25: Type c(单Type C 接口)(VL162) | I25: N-6W | J25: 0+32G | K25: 选配 | L25: 现询 | M25: 选配 | N25: =18.22/E25/1.13 -> 2.388725 | O25: =24.73/6.78/1.13*1.05 -> 3.3892631 | P25: =28.52/E25/1.13 -> 3.7391019 | Q25: 16.1 | R25: =26.66/E25/1.13 -> 3.4952475 | S25: =SUBTOTAL(109,P25:R25) -> 23.334349 | T25: 14 | U25: 0+EMMC5.1 32GB | V25: HDMI2.0:IT66318FN; RJ45:RTL8125BG; USB3-10G:GL9901VAE; ROM:128Mb
A26: 2 | B26: DNP59（6L+通孔+OSP） | C26: 134.16*126.50*1.0mm | D26: 20251020 | E26: 6.75 | F26: A.F.M.2501663 | G26: SKU3 | H26: 单Type IC及Type C 单接口(RTS5453H) | I26: N-6W | J26: 8G*2+0 | K26: AX201.D2WG | L26: 现询 | M26: 选配 | N26: =17.59/E26/1.13 -> 2.3061291 | O26: 2.7470068 | P26: 3.0217074 | Q26: 18.2 | R26: 3.5749467 | S26: =SUBTOTAL(109,P26:R26) -> 24.796654 | T26: 15.6 | U26: LPDDR5-315球8G | V26: 全功能(RTS5453H)；含TPM
